Workbook

Sheet Read me
A1: Manual two-player checklist: Issue Reports #6 and #7
A3: About
A4: Date / baseline | B4: 2026-10-20. HEAD = b7e7b91 ('current medium task completed'). Line numbers in the code edits are at this commit.
A5: Sources | B5: Issue Report #6 §5 step 1 and its checklist Docs/AI/ManualChecks/2026-10-19_ManualChecks-Report6.md; Issue Report #7 §5 step 1 and §9 of the 13 removed specs (git show b7e7b91:Docs/AI/Tasks/<file>).
A6: Why | B6: None of the gameplay fixes from reports #6 and #7 has been seen in a real two-player match yet (report #7 summary). This is the main open item, together with one fresh player build (U1).
A7: Who runs it | B7: The developer, in the Unity Editor with the ParrelSync clone. These checks need two running instances, so the AI agents can't run them.
A8: Order | B8: A first: no changes, and it covers most of the risk. Then B (temporary Inspector and asset changes) and C (temporary code edits); revert both on the Temp changes sheet. D (player build) last, after every revert.
A9: How to report | B9: 1. Set Status on every row of the Checklist sheet. The Summary sheet updates by itself. 2. For every Fail, paste the Console text (error plus stack trace) into 'Console output / notes'. Clear on Play is on, so copy it before you press Play again. 3. Tell Claude when you're done. Claude then updates the report and writes fix specs if needed.
A11: Legend
A12: Cells to fill in | B12: Only the yellow cells: Checklist → Status, Tested by, Date, Console output / notes; Temp changes → Applied, Reverted. Everything else is reference text or formulas.
A13: Pass | B13: Every expected result in the row was seen.
A14: Fail | B14: At least one expected result wasn't seen, or a new error appeared. Add the Console text.
A15: Blocked | B15: The row couldn't be run (e.g. an earlier failure, no Clarity drawn, network needed). Say why in the notes.
A16: Not run | B16: Skipped on purpose. Fine for optional rows; for a required row it keeps the group open.
A17: N/A | B17: Doesn't apply in this setup. Counts like a Pass for the group result.
A18: Optional = Yes | B18: Optional rows don't hold back a group's Pass result.
A19: Grey text | B19: In a group's second and later rows, Check / Covers / Report / Run as / Temp change repeat the first row so that filtering works. 'Steps' on those rows only adds the row's own variant.
A21: Example of a filled row
A22: ID / Status | B22: A2.2 → Fail
A23: Tested by / Date | B23: Host window / 2026-10-21
A24: Console output / notes | B24: The Turn resumed from 0, not from about 20. Console: <paste the error and stack trace here>.
A26: Preparation
A27: 1. Two Editors | B27: Open the main project. Open the clone with ParrelSync → Clones Manager → Open in New Editor. The clone shares Assets, so make every temporary change in the main project only.
A28: 2. Console | B28: In both Editors, open the Console: Collapse off, Clear on Play on.
A29: 3. Clean start | B29: git status shows no changes to the files on the Temp changes sheet. Both windows are in English (main menu → Settings).
A30: 4. Start a match | B30: Log in and go to the Lobby in both windows. Window 1 presses Create Lobby: from now on it's the host window. Window 2 presses Find Lobby, selects the lobby and presses Join: it's the client window. The host presses Start game.
A31: 5. Phase log | B31: GameMasterPrefab has m_debugMode = 1, so the host Console logs every phase: 'Round break phase started', 'DrawPhase started', 'Card selection phase started.', 'Player Action phase started', 'Waiting for Respawn', 'GameMaster: match ended …'.
A33: Useful facts
A34: Phases (en) | B34: 'Round preparation' (5 s). It still shows during card dealing (~3 s), because the game never switches to a draw phase. Then 'Card Selection' (60 s), 'Turn' (60 s per player) and 'Waiting for respawn' (30 s). The timer counts up (elapsed seconds).
A35: Turn order | B35: The player whose selected cards (play and discard) cost more goes first. To go second, select fewer or cheaper cards than the opponent.
A36: Controls | B36: Hand cards: left-click = play, right-click = discard. Confirm turn confirms the selection in Card Selection, ends your Turn, and confirms the respawn block in Waiting for respawn. Cast in your Turn: left-click a board card → click the target in the world → Confirm → Send. W/A/S/D = one step (own Turn only). Space = −10 HP to yourself (debug, own Turn only).
A37: Cards | B37: Iceshard: 2 mana, 20 damage to the opponent's pony. Fireball: 3 mana, 50 damage to an opponent block (2 hits destroy a block). Clarity: 3 mana, draw 2. HealingHooves: 4 mana, heal yourself 30.
A38: Numbers | B38: Pony HP 100, block HP 100, 3 lives, 25 blocks per player. Mana 2 → 4 → 6 … up to 20. 2 new cards per player per round. Hand limit 10: over it, the oldest uncommitted cards are discarded.
A39: Kill a pony at any moment | B39: In the host window's Scene view, select the pony (PonyBase(Clone)) and drag it sideways off its platform, or add about 20 to its Transform Position X or Z. It falls into the lava and dies, in any phase. Host window only: the lava check runs on the server.
A40: Respawn | B40: In 'Waiting for respawn', the dead player clicks one of their own blocks and presses Confirm turn. With no choice, a random block is used after 30 s.
A41: Switch language | B41: Main menu → Settings (new in M12; the choice is remembered). In the lobby or during a match: Window → Asset Management → Localization Scene Controls → Active Locale.
A43: Changes from the report #6 checklist
A44: IDs | B44: Report #6's IDs (A1–A13, B1–B4, C1–C4, D) are unchanged. Report #7 adds A14–A21, B5–B8, C5–C7 and three rows in D.
A45: Now fixed | B45: The N20 Send NullReferenceException, the M10 LobbyService exception and the CS0114 warning were 'known issues' in report #6. They're fixed now: mark the row Fail if you see them (Known issues sheet, second table).
A46: B1 (deck refill) | B46: Since M15 the 10-card hand limit discards extra draws by itself, so the old 'discard about 10 cards' step is gone, and 'Hand limit reached…' messages are expected.
...

Sheet Checklist
A1: Manual two-player checklist: Issue Reports #6 and #7
A2: Baseline b7e7b91 (2026-10-20). Fill in only the yellow columns (Status, Tested by, Date, Console output / notes). Temp-change IDs (T1–T16) are on the Temp changes sheet; expected noise is on the Known issues sheet.
A3: ID | B3: Group | C3: Check | D3: Covers | E3: Report | F3: Run as | G3: Temp change | H3: Steps | I3: Expected result | J3: Optional | K3: Status | L3: Tested by | M3: Date | N3: Console output / notes
A4: A. Normal settings (no temporary changes)
A5: A1.1 | B5: A1 | C5: Baseline rounds and mana | D5: N18, MANA1–3, U12, M11 | E5: #6 | F5: Both | G5: — | H5: Start a match (Read me → Preparation). Play 3 rounds with no deaths. Check both windows, so the client is a real remote client (U12). | I5: Both windows show their own and the opponent's mana as 2/2 → 4/4 → 6/6 at the start of rounds 1–3. | K5: Pass | L5: Owner | M5: 46315 | N5: NetworkVariable is written to, but doesn't know its NetworkBehaviour yet. Are you modifying a NetworkVariable before the NetworkObject is spawned? | O5: Have warning at the start of game
A6: A1.2 | B6: A1 | C6: Baseline rounds and mana | D6: N18, MANA1–3, U12, M11 | E6: #6 | F6: Both | G6: — | I6: After a confirm, current mana goes down by the cost of the played cards, on both windows. | K6: Pass | L6: Owner | M6: 46315
A7: A1.3 | B7: A1 | C7: Baseline rounds and mana | D7: N18, MANA1–3, U12, M11 | E7: #6 | F7: Both | G7: — | I7: Round 1 (2 mana): Fireball or Clarity (3) can't be selected to play (no highlight). Iceshard (2) can. | K7: Pass | L7: Owner | M7: 46315
A8: A1.4 | B8: A1 | C8: Baseline rounds and mana | D8: N18, MANA1–3, U12, M11 | E8: #6 | F8: Both | G8: — | I8: Round 2 (4 mana): HealingHooves alone can be selected. HealingHooves + Iceshard can't. | K8: Pass | L8: Owner | M8: 46315
A9: A1.5 | B9: A1 | C9: Baseline rounds and mana | D9: N18, MANA1–3, U12, M11 | E9: #6 | F9: Both | G9: — | I9: Discarding any number of cards (right-click) is allowed and costs no mana. | K9: Pass | L9: Owner | M9: 46315
A10: A1.6 | B10: A1 | C10: Baseline rounds and mana | D10: N18, MANA1–3, U12, M11 | E10: #6 | F10: Both | G10: — | I10: Timing is as before: ~5 s preparation, ~3 s dealing; selection ends when both confirm or at 60 s. | K10: Pass | L10: Owner | M10: 46315
A11: A1.7 | B11: A1 | C11: Baseline rounds and mana | D11: N18, MANA1–3, U12, M11 | E11: #6 | F11: Both | G11: — | I11: No errors except the ones on the Known issues sheet. | K11: Pass | L11: Owner | M11: 46315 | O11: Only warning
A12: A2.1 | B12: A2 | C12: Death in your own Turn: the timer resumes | D12: M1, N18_M1 | E12: #6 | F12: Either | G12: — | H12: In your own Turn, wait until the timer shows about 20. Walk off the platform edge, or press Space 10 times. In 'Waiting for respawn', wait about 10 s, then pick a block and press Confirm turn. | I12: 'Waiting for respawn' starts as soon as the pony dies. | K12: Pass | L12: Owner | M12: 46315
A13: A2.2 | B13: A2 | C13: Death in your own Turn: the timer resumes | D13: M1, N18_M1 | E13: #6 | F13: Either | G13: — | I13: After the respawn, the same player's Turn continues from about 20 (not from 0, and not from about 10). | K13: Pass | L13: Owner | M13: 46315
A14: A2.3 | B14: A2 | C14: Death in your own Turn: the timer resumes | D14: M1, N18_M1 | E14: #6 | F14: Either | G14: — | I14: The pony appears on the chosen block, and lives went from 3 to 2. | K14: Pass | L14: Owner | M14: 46315
A15: A3.1 | B15: A3 | C15: Death during Round preparation | D15: N18 | E15: #6 | F15: Host (Scene view) | G15: — | H15: During 'Round preparation', kill a pony through the host Scene view (Read me → Useful facts). Without the Scene view trick: as the second player, walk off the edge and press Confirm turn at once, so the fall ends after your Turn. | I15: 'Waiting for respawn' starts at once. It doesn't wait for the next Turn. | K15: Pass | L15: Owner | M15: 46315
A16: A3.2 | B16: A3 | C16: Death during Round preparation | D16: N18 | E16: #6 | F16: Host (Scene view) | G16: — | I16: After the respawn, 'Round preparation' continues from the time it had reached, then cards are dealt, then Card Selection starts. | K16: Pass | L16: Owner | M16: 46315
A17: A3.3 | B17: A3 | C17: Death during Round preparation | D17: N18 | E17: #6 | F17: Host (Scene view) | G17: — | I17: Mana grew only once this round. For example, round 2 shows 4/4, not 6/6. | K17: Pass | L17: Owner | M17: 46315
A18: A4.1 | B18: A4 | C18: Death while cards are dealt | D18: N18 | E18: #6 | F18: Host (Scene view) | G18: T2 (optional) | H18: Right after 'Round preparation' reaches 5, the cards are dealt (~3 s; the host Console shows 'DrawPhase started'). Kill a pony in that window. Optional: to widen the window, set GameMasterPrefab → m_cardDrawDelay = 3 (T2), and revert it afterwards. | I18: 'Waiting for respawn' starts at once. | K18: Pass | L18: Owner | M18: 46315
A19: A4.2 | B19: A4 | C19: Death while cards are dealt | D19: N18 | E19: #6 | F19: Host (Scene view) | G19: T2 (optional) | I19: After the respawn, the remaining cards are dealt. Each player gets exactly 2 new cards this round: none twice, none skipped. | K19: Pass | L19: Owner | M19: 46315
A20: A5.1 | B20: A5 | C20: Death during Card Selection: selections are kept | D20: N18_M1 | E20: #6 | F20: Both | G20: — | H20: 1. In Card Selection, player A selects cards and presses Confirm turn. 2. Player B highlights 1 play card (left-click) and 1 discard card (right-click), but doesn't confirm. 3. Note the timer, then kill either pony. 4. Respawn. | I20: Card Selection continues from the noted time. | K20: Pass | L20: Owner | M20: 46315
A21: A5.2 | B21: A5 | C21: Death during Card Selection: selections are kept | D21: N18_M1 | E21: #6 | F21: Both | G21: — | I21: B's two highlights are back, in their play and discard colors. | K21: Pass | L21: Owner | M21: 46315
A22: A5.3 | B22: A5 | C22: Death during Card Selection: selections are kept | D22: N18_M1 | E22: #6 | F22: Both | G22: — | I22: A doesn't need to confirm again: the phase ends when B confirms. | K22: Pass | L22: Owner | M22: 46315
A23: A5.4 | B23: A5 | C23: Death during Card Selection: selections are kept | D23: N18_M1 | E23: #6 | F23: Both | G23: — | I23: After B confirms, exactly the highlighted cards appear on B's board. | K23: Pass | L23: Owner | M23: 46315
A24: A6.1 | B24: A6 | C24: A last-life death ends the match at once | D24: N18 | E24: #6 | F24: Both | G24: — | H24: Bring one player down to 1 life with two earlier deaths (A2–A5 count). Then kill them again, once in 'Round preparation' or Card Selection. If you play more matches, also try a Turn. | I24: There's no 'Waiting for respawn'. | K24: Pass | L24: Owner | M24: 46315
A25: A6.2 | B25: A6 | C25: A last-life death ends the match at once | D25: N18 | E25: #6 | F25: Both | G25: — | I25: Both windows go to the result screen right away, with the right titles and reasons ('You won' / 'You lost' plus the lives reason). | K25: Pass | L25: Owner | M25: 46315
A26: A7.1 | B26: A7 | C26: Leave match: the client, during Card Selection | D26: N19, N1 | E26: #6 | F26: Client | G26: — | H26: The client clicks Leave match → Cancel. Then Leave match → Leave. | I26: Cancel closes the dialog and nothing else changes. | K26: Pass | L26: Owner | M26: 46315
A27: A7.2 | B27: A7 | C27: Leave match: the client, during Card Selection | D27: N19, N1 | E27: #6 | F27: Client | G27: — | I27: After Leave, the client sees 'You lost' + 'You left the match.', and the host sees 'You won' + 'Your opponent left the match.' | K27: Pass | L27: Owner | M27: 46315
A28: A7.3 | B28: A7 | C28: Leave match: the client, during Card Selection | D28: N19, N1 | E28: #6 | F28: Client | G28: — | I28: Press Main menu on both windows, create a new lobby and start a new match. It works normally, with no errors. | K28: Pass | L28: Owner | M28: 46315
A29: A8.1 | B29: A8 | C29: Leave match at other moments | D29: N19 | E29: #6 | F29: Both | G29: — | H29: Run one match for each row. (a) The host leaves during its own Turn. | I29: One result on both windows. The leaver loses. No errors. | K29: Pass | L29: Owner | M29: 46315
A30: A8.2 | B30: A8 | C30: Leave match at other moments | D30: N19 | E30: #6 | F30: Both | G30: — | H30: (b) Either player leaves during the opponent's Turn. | I30: One result on both windows. The leaver loses. No errors. | K30: Pass | L30: Owner | M30: 46315
A31: A8.3 | B31: A8 | C31: Leave match at other moments | D31: N19 | E31: #6 | F31: Both | G31: — | H31: (c1) During 'Waiting for respawn', the dead player leaves. | I31: One result on both windows. The leaver loses. No errors. | K31: Pass | L31: Owner | M31: 46315
A32: A8.4 | B32: A8 | C32: Leave match at other moments | D32: N19 | E32: #6 | F32: Both | G32: — | H32: (c2) During 'Waiting for respawn', the other player leaves. | I32: One result on both windows. The leaver loses. No errors. | K32: Pass | L32: Owner | M32: 46315
A33: A8.5 | B33: A8 | C33: Leave match at other moments | D33: N19 | E33: #6 | F33: Both | G33: — | H33: (d) Double-click Leave quickly. | I33: Only one result on both windows. | K33: Pass | L33: Owner | M33: 46315
A34: A9.1 | B34: A9 | C34: The Leave dialog blocks clicks behind it | D34: N19 | E34: #6 | F34: Either | G34: — | H34: Open the Leave dialog. Click hand cards, board cards, blocks and ponies through the dimmed background. | I34: Nothing gets selected or targeted. After Cancel the game continues normally. | K34: Pass | L34: Owner | M34: 46315
A35: A9.2 | B35: A9 | C35: The Leave dialog blocks clicks behind it | D35: N19 | E35: #6 | F35: Either | G35: — | H35: Game view at 16:9, then one other aspect ratio (e.g. 16:10 or 4:3). | I35: The Leave button doesn't cover the hand, the mana labels or the announcer. | K35: Pass | L35: Owner | M35: 46315
A36: A10.1 | B36: A10 | C36: Languages in a match and on the result screen | D36: N19, MANA3, H10 | E36: #6 | F36: Either | G36: — | H36: During a match, with the Leave dialog open, switch the locale to ru, then ja, then back to en (Window → Asset Management → Localization Scene Controls → Active Locale). Do the same on a result screen. | I36: The Leave button, dialog text, Leave and Cancel are translated and fit: no clipping, no □ boxes. | K36: Pass | L36: Owner | M36: 46315
A37: A10.2 | B37: A10 | C37: Languages in a match and on the result screen | D37: N19, MANA3, H10 | E37: #6 | F37: Either | G37: — | I37: The mana labels are translated. | K37: Pass | L37: Owner | M37: 46315
A38: A10.3 | B38: A10 | C38: Languages in a match and on the result screen | D38: N19, MANA3, H10 | E38: #6 | F38: Either | G38: — | I38: The result title and reason are translated, including 'You left the match.' | K38: Pass | L38: Owner | M38: 46315
A39: A11.1 | B39: A11 | C39: A disconnect counts as a forfeit | D39: H6, U10 | E39: #6 | F39: Client leaves | G39: — | H39: In separate matches, stop Play Mode in the client window at the moment named in each row. (a) During 'Round preparation'. | I39: The host gets 'You won' + 'Your opponent left the match.' within a few seconds. No errors on the host. | K39: Pass | L39: Owner | M39: 46315
A40: A11.2 | B40: A11 | C40: A disconnect counts as a forfeit | D40: H6, U10 | E40: #6 | F40: Client leaves | G40: — | H40: (b) During Card Selection. | I40: Same as (a). | K40: Pass | L40: Owner | M40: 46315
...

Sheet Summary
A1: Results summary
A2: Calculated from the Checklist sheet; don't edit. Result: Fail if any row failed, Blocked if any row is blocked, Pass when every required row is Pass or N/A. Optional rows don't hold back a Pass; a group with only optional rows shows 'Optional' until one is run.
A4: Group | B4: Check | C4: Covers | D4: Report | E4: Items | F4: Required | G4: Pass | H4: Fail | I4: Blocked | J4: N/A | K4: Not run / empty | L4: Open (required) | M4: Done % | N4: Result
A5: A1 | B5: Baseline rounds and mana | C5: N18, MANA1–3, U12, M11 | D5: #6 | E5: =COUNTIF(Checklist!$B$4:$B$130,$A5) -> 7 | F5: =COUNTIFS(Checklist!$B$4:$B$130,$A5,Checklist!$J$4:$J$130,"<>Yes") -> 7 | G5: =COUNTIFS(Checklist!$B$4:$B$130,$A5,Checklist!$K$4:$K$130,"Pass") -> 7 | H5: =COUNTIFS(Checklist!$B$4:$B$130,$A5,Checklist!$K$4:$K$130,"Fail") -> 0 | I5: =COUNTIFS(Checklist!$B$4:$B$130,$A5,Checklist!$K$4:$K$130,"Blocked") -> 0 | J5: =COUNTIFS(Checklist!$B$4:$B$130,$A5,Checklist!$K$4:$K$130,"N/A") -> 0 | K5: =E5-G5-H5-I5-J5 -> 0 | L5: =COUNTIFS(Checklist!$B$4:$B$130,$A5,Checklist!$J$4:$J$130,"<>Yes",Checklist!$K$4:$K$130,"<>Pass",Checklist!$K$4:$K$130,"<>N/A") -> 0 | M5: =IF(E5=0,0,(G5+H5+I5+J5)/E5) -> 1 | N5: =IF(H5>0,"Fail",IF(I5>0,"Blocked",IF(G5+H5+I5+J5=0,IF(F5=0,"Optional","Not started"),IF(L5=0,"Pass","In progress")))) -> Pass
A6: A2 | B6: Death in your own Turn: the timer resumes | C6: M1, N18_M1 | D6: #6 | E6: =COUNTIF(Checklist!$B$4:$B$130,$A6) -> 3 | F6: =COUNTIFS(Checklist!$B$4:$B$130,$A6,Checklist!$J$4:$J$130,"<>Yes") -> 3 | G6: =COUNTIFS(Checklist!$B$4:$B$130,$A6,Checklist!$K$4:$K$130,"Pass") -> 3 | H6: =COUNTIFS(Checklist!$B$4:$B$130,$A6,Checklist!$K$4:$K$130,"Fail") -> 0 | I6: =COUNTIFS(Checklist!$B$4:$B$130,$A6,Checklist!$K$4:$K$130,"Blocked") -> 0 | J6: =COUNTIFS(Checklist!$B$4:$B$130,$A6,Checklist!$K$4:$K$130,"N/A") -> 0 | K6: =E6-G6-H6-I6-J6 -> 0 | L6: =COUNTIFS(Checklist!$B$4:$B$130,$A6,Checklist!$J$4:$J$130,"<>Yes",Checklist!$K$4:$K$130,"<>Pass",Checklist!$K$4:$K$130,"<>N/A") -> 0 | M6: =IF(E6=0,0,(G6+H6+I6+J6)/E6) -> 1 | N6: =IF(H6>0,"Fail",IF(I6>0,"Blocked",IF(G6+H6+I6+J6=0,IF(F6=0,"Optional","Not started"),IF(L6=0,"Pass","In progress")))) -> Pass
A7: A3 | B7: Death during Round preparation | C7: N18 | D7: #6 | E7: =COUNTIF(Checklist!$B$4:$B$130,$A7) -> 3 | F7: =COUNTIFS(Checklist!$B$4:$B$130,$A7,Checklist!$J$4:$J$130,"<>Yes") -> 3 | G7: =COUNTIFS(Checklist!$B$4:$B$130,$A7,Checklist!$K$4:$K$130,"Pass") -> 3 | H7: =COUNTIFS(Checklist!$B$4:$B$130,$A7,Checklist!$K$4:$K$130,"Fail") -> 0 | I7: =COUNTIFS(Checklist!$B$4:$B$130,$A7,Checklist!$K$4:$K$130,"Blocked") -> 0 | J7: =COUNTIFS(Checklist!$B$4:$B$130,$A7,Checklist!$K$4:$K$130,"N/A") -> 0 | K7: =E7-G7-H7-I7-J7 -> 0 | L7: =COUNTIFS(Checklist!$B$4:$B$130,$A7,Checklist!$J$4:$J$130,"<>Yes",Checklist!$K$4:$K$130,"<>Pass",Checklist!$K$4:$K$130,"<>N/A") -> 0 | M7: =IF(E7=0,0,(G7+H7+I7+J7)/E7) -> 1 | N7: =IF(H7>0,"Fail",IF(I7>0,"Blocked",IF(G7+H7+I7+J7=0,IF(F7=0,"Optional","Not started"),IF(L7=0,"Pass","In progress")))) -> Pass
A8: A4 | B8: Death while cards are dealt | C8: N18 | D8: #6 | E8: =COUNTIF(Checklist!$B$4:$B$130,$A8) -> 2 | F8: =COUNTIFS(Checklist!$B$4:$B$130,$A8,Checklist!$J$4:$J$130,"<>Yes") -> 2 | G8: =COUNTIFS(Checklist!$B$4:$B$130,$A8,Checklist!$K$4:$K$130,"Pass") -> 2 | H8: =COUNTIFS(Checklist!$B$4:$B$130,$A8,Checklist!$K$4:$K$130,"Fail") -> 0 | I8: =COUNTIFS(Checklist!$B$4:$B$130,$A8,Checklist!$K$4:$K$130,"Blocked") -> 0 | J8: =COUNTIFS(Checklist!$B$4:$B$130,$A8,Checklist!$K$4:$K$130,"N/A") -> 0 | K8: =E8-G8-H8-I8-J8 -> 0 | L8: =COUNTIFS(Checklist!$B$4:$B$130,$A8,Checklist!$J$4:$J$130,"<>Yes",Checklist!$K$4:$K$130,"<>Pass",Checklist!$K$4:$K$130,"<>N/A") -> 0 | M8: =IF(E8=0,0,(G8+H8+I8+J8)/E8) -> 1 | N8: =IF(H8>0,"Fail",IF(I8>0,"Blocked",IF(G8+H8+I8+J8=0,IF(F8=0,"Optional","Not started"),IF(L8=0,"Pass","In progress")))) -> Pass
A9: A5 | B9: Death during Card Selection: selections are kept | C9: N18_M1 | D9: #6 | E9: =COUNTIF(Checklist!$B$4:$B$130,$A9) -> 4 | F9: =COUNTIFS(Checklist!$B$4:$B$130,$A9,Checklist!$J$4:$J$130,"<>Yes") -> 4 | G9: =COUNTIFS(Checklist!$B$4:$B$130,$A9,Checklist!$K$4:$K$130,"Pass") -> 4 | H9: =COUNTIFS(Checklist!$B$4:$B$130,$A9,Checklist!$K$4:$K$130,"Fail") -> 0 | I9: =COUNTIFS(Checklist!$B$4:$B$130,$A9,Checklist!$K$4:$K$130,"Blocked") -> 0 | J9: =COUNTIFS(Checklist!$B$4:$B$130,$A9,Checklist!$K$4:$K$130,"N/A") -> 0 | K9: =E9-G9-H9-I9-J9 -> 0 | L9: =COUNTIFS(Checklist!$B$4:$B$130,$A9,Checklist!$J$4:$J$130,"<>Yes",Checklist!$K$4:$K$130,"<>Pass",Checklist!$K$4:$K$130,"<>N/A") -> 0 | M9: =IF(E9=0,0,(G9+H9+I9+J9)/E9) -> 1 | N9: =IF(H9>0,"Fail",IF(I9>0,"Blocked",IF(G9+H9+I9+J9=0,IF(F9=0,"Optional","Not started"),IF(L9=0,"Pass","In progress")))) -> Pass
A10: A6 | B10: A last-life death ends the match at once | C10: N18 | D10: #6 | E10: =COUNTIF(Checklist!$B$4:$B$130,$A10) -> 2 | F10: =COUNTIFS(Checklist!$B$4:$B$130,$A10,Checklist!$J$4:$J$130,"<>Yes") -> 2 | G10: =COUNTIFS(Checklist!$B$4:$B$130,$A10,Checklist!$K$4:$K$130,"Pass") -> 2 | H10: =COUNTIFS(Checklist!$B$4:$B$130,$A10,Checklist!$K$4:$K$130,"Fail") -> 0 | I10: =COUNTIFS(Checklist!$B$4:$B$130,$A10,Checklist!$K$4:$K$130,"Blocked") -> 0 | J10: =COUNTIFS(Checklist!$B$4:$B$130,$A10,Checklist!$K$4:$K$130,"N/A") -> 0 | K10: =E10-G10-H10-I10-J10 -> 0 | L10: =COUNTIFS(Checklist!$B$4:$B$130,$A10,Checklist!$J$4:$J$130,"<>Yes",Checklist!$K$4:$K$130,"<>Pass",Checklist!$K$4:$K$130,"<>N/A") -> 0 | M10: =IF(E10=0,0,(G10+H10+I10+J10)/E10) -> 1 | N10: =IF(H10>0,"Fail",IF(I10>0,"Blocked",IF(G10+H10+I10+J10=0,IF(F10=0,"Optional","Not started"),IF(L10=0,"Pass","In progress")))) -> Pass
A11: A7 | B11: Leave match: the client, during Card Selection | C11: N19, N1 | D11: #6 | E11: =COUNTIF(Checklist!$B$4:$B$130,$A11) -> 3 | F11: =COUNTIFS(Checklist!$B$4:$B$130,$A11,Checklist!$J$4:$J$130,"<>Yes") -> 3 | G11: =COUNTIFS(Checklist!$B$4:$B$130,$A11,Checklist!$K$4:$K$130,"Pass") -> 3 | H11: =COUNTIFS(Checklist!$B$4:$B$130,$A11,Checklist!$K$4:$K$130,"Fail") -> 0 | I11: =COUNTIFS(Checklist!$B$4:$B$130,$A11,Checklist!$K$4:$K$130,"Blocked") -> 0 | J11: =COUNTIFS(Checklist!$B$4:$B$130,$A11,Checklist!$K$4:$K$130,"N/A") -> 0 | K11: =E11-G11-H11-I11-J11 -> 0 | L11: =COUNTIFS(Checklist!$B$4:$B$130,$A11,Checklist!$J$4:$J$130,"<>Yes",Checklist!$K$4:$K$130,"<>Pass",Checklist!$K$4:$K$130,"<>N/A") -> 0 | M11: =IF(E11=0,0,(G11+H11+I11+J11)/E11) -> 1 | N11: =IF(H11>0,"Fail",IF(I11>0,"Blocked",IF(G11+H11+I11+J11=0,IF(F11=0,"Optional","Not started"),IF(L11=0,"Pass","In progress")))) -> Pass
A12: A8 | B12: Leave match at other moments | C12: N19 | D12: #6 | E12: =COUNTIF(Checklist!$B$4:$B$130,$A12) -> 5 | F12: =COUNTIFS(Checklist!$B$4:$B$130,$A12,Checklist!$J$4:$J$130,"<>Yes") -> 5 | G12: =COUNTIFS(Checklist!$B$4:$B$130,$A12,Checklist!$K$4:$K$130,"Pass") -> 5 | H12: =COUNTIFS(Checklist!$B$4:$B$130,$A12,Checklist!$K$4:$K$130,"Fail") -> 0 | I12: =COUNTIFS(Checklist!$B$4:$B$130,$A12,Checklist!$K$4:$K$130,"Blocked") -> 0 | J12: =COUNTIFS(Checklist!$B$4:$B$130,$A12,Checklist!$K$4:$K$130,"N/A") -> 0 | K12: =E12-G12-H12-I12-J12 -> 0 | L12: =COUNTIFS(Checklist!$B$4:$B$130,$A12,Checklist!$J$4:$J$130,"<>Yes",Checklist!$K$4:$K$130,"<>Pass",Checklist!$K$4:$K$130,"<>N/A") -> 0 | M12: =IF(E12=0,0,(G12+H12+I12+J12)/E12) -> 1 | N12: =IF(H12>0,"Fail",IF(I12>0,"Blocked",IF(G12+H12+I12+J12=0,IF(F12=0,"Optional","Not started"),IF(L12=0,"Pass","In progress")))) -> Pass
A13: A9 | B13: The Leave dialog blocks clicks behind it | C13: N19 | D13: #6 | E13: =COUNTIF(Checklist!$B$4:$B$130,$A13) -> 2 | F13: =COUNTIFS(Checklist!$B$4:$B$130,$A13,Checklist!$J$4:$J$130,"<>Yes") -> 2 | G13: =COUNTIFS(Checklist!$B$4:$B$130,$A13,Checklist!$K$4:$K$130,"Pass") -> 2 | H13: =COUNTIFS(Checklist!$B$4:$B$130,$A13,Checklist!$K$4:$K$130,"Fail") -> 0 | I13: =COUNTIFS(Checklist!$B$4:$B$130,$A13,Checklist!$K$4:$K$130,"Blocked") -> 0 | J13: =COUNTIFS(Checklist!$B$4:$B$130,$A13,Checklist!$K$4:$K$130,"N/A") -> 0 | K13: =E13-G13-H13-I13-J13 -> 0 | L13: =COUNTIFS(Checklist!$B$4:$B$130,$A13,Checklist!$J$4:$J$130,"<>Yes",Checklist!$K$4:$K$130,"<>Pass",Checklist!$K$4:$K$130,"<>N/A") -> 0 | M13: =IF(E13=0,0,(G13+H13+I13+J13)/E13) -> 1 | N13: =IF(H13>0,"Fail",IF(I13>0,"Blocked",IF(G13+H13+I13+J13=0,IF(F13=0,"Optional","Not started"),IF(L13=0,"Pass","In progress")))) -> Pass
A14: A10 | B14: Languages in a match and on the result screen | C14: N19, MANA3, H10 | D14: #6 | E14: =COUNTIF(Checklist!$B$4:$B$130,$A14) -> 3 | F14: =COUNTIFS(Checklist!$B$4:$B$130,$A14,Checklist!$J$4:$J$130,"<>Yes") -> 3 | G14: =COUNTIFS(Checklist!$B$4:$B$130,$A14,Checklist!$K$4:$K$130,"Pass") -> 3 | H14: =COUNTIFS(Checklist!$B$4:$B$130,$A14,Checklist!$K$4:$K$130,"Fail") -> 0 | I14: =COUNTIFS(Checklist!$B$4:$B$130,$A14,Checklist!$K$4:$K$130,"Blocked") -> 0 | J14: =COUNTIFS(Checklist!$B$4:$B$130,$A14,Checklist!$K$4:$K$130,"N/A") -> 0 | K14: =E14-G14-H14-I14-J14 -> 0 | L14: =COUNTIFS(Checklist!$B$4:$B$130,$A14,Checklist!$J$4:$J$130,"<>Yes",Checklist!$K$4:$K$130,"<>Pass",Checklist!$K$4:$K$130,"<>N/A") -> 0 | M14: =IF(E14=0,0,(G14+H14+I14+J14)/E14) -> 1 | N14: =IF(H14>0,"Fail",IF(I14>0,"Blocked",IF(G14+H14+I14+J14=0,IF(F14=0,"Optional","Not started"),IF(L14=0,"Pass","In progress")))) -> Pass
A15: A11 | B15: A disconnect counts as a forfeit | C15: H6, U10 | D15: #6 | E15: =COUNTIF(Checklist!$B$4:$B$130,$A15) -> 7 | F15: =COUNTIFS(Checklist!$B$4:$B$130,$A15,Checklist!$J$4:$J$130,"<>Yes") -> 7 | G15: =COUNTIFS(Checklist!$B$4:$B$130,$A15,Checklist!$K$4:$K$130,"Pass") -> 7 | H15: =COUNTIFS(Checklist!$B$4:$B$130,$A15,Checklist!$K$4:$K$130,"Fail") -> 0 | I15: =COUNTIFS(Checklist!$B$4:$B$130,$A15,Checklist!$K$4:$K$130,"Blocked") -> 0 | J15: =COUNTIFS(Checklist!$B$4:$B$130,$A15,Checklist!$K$4:$K$130,"N/A") -> 0 | K15: =E15-G15-H15-I15-J15 -> 0 | L15: =COUNTIFS(Checklist!$B$4:$B$130,$A15,Checklist!$J$4:$J$130,"<>Yes",Checklist!$K$4:$K$130,"<>Pass",Checklist!$K$4:$K$130,"<>N/A") -> 0 | M15: =IF(E15=0,0,(G15+H15+I15+J15)/E15) -> 1 | N15: =IF(H15>0,"Fail",IF(I15>0,"Blocked",IF(G15+H15+I15+J15=0,IF(F15=0,"Optional","Not started"),IF(L15=0,"Pass","In progress")))) -> Pass
A16: A12 | B16: Nothing is left over after a match | C16: H7, U8 | D16: #6 | E16: =COUNTIF(Checklist!$B$4:$B$130,$A16) -> 2 | F16: =COUNTIFS(Checklist!$B$4:$B$130,$A16,Checklist!$J$4:$J$130,"<>Yes") -> 2 | G16: =COUNTIFS(Checklist!$B$4:$B$130,$A16,Checklist!$K$4:$K$130,"Pass") -> 2 | H16: =COUNTIFS(Checklist!$B$4:$B$130,$A16,Checklist!$K$4:$K$130,"Fail") -> 0 | I16: =COUNTIFS(Checklist!$B$4:$B$130,$A16,Checklist!$K$4:$K$130,"Blocked") -> 0 | J16: =COUNTIFS(Checklist!$B$4:$B$130,$A16,Checklist!$K$4:$K$130,"N/A") -> 0 | K16: =E16-G16-H16-I16-J16 -> 0 | L16: =COUNTIFS(Checklist!$B$4:$B$130,$A16,Checklist!$J$4:$J$130,"<>Yes",Checklist!$K$4:$K$130,"<>Pass",Checklist!$K$4:$K$130,"<>N/A") -> 0 | M16: =IF(E16=0,0,(G16+H16+I16+J16)/E16) -> 1 | N16: =IF(H16>0,"Fail",IF(I16>0,"Blocked",IF(G16+H16+I16+J16=0,IF(F16=0,"Optional","Not started"),IF(L16=0,"Pass","In progress")))) -> Pass
... A40: D | B40: Windows player build | C40: U1, M12 | D40: #6 + #7 | E40: =COUNTIF(Checklist!$B$4:$B$130,$A40) -> 5 | F40: =COUNTIFS(Checklist!$B$4:$B$130,$A40,Checklist!$J$4:$J$130,"<>Yes") -> 4 | G40: =COUNTIFS(Checklist!$B$4:$B$130,$A40,Checklist!$K$4:$K$130,"Pass") -> 5 | H40: =COUNTIFS(Checklist!$B$4:$B$130,$A40,Checklist!$K$4:$K$130,"Fail") -> 0 | I40: =COUNTIFS(Checklist!$B$4:$B$130,$A40,Checklist!$K$4:$K$130,"Blocked") -> 0 | J40: =COUNTIFS(Checklist!$B$4:$B$130,$A40,Checklist!$K$4:$K$130,"N/A") -> 0 | K40: =E40-G40-H40-I40-J40 -> 0 | L40: =COUNTIFS(Checklist!$B$4:$B$130,$A40,Checklist!$J$4:$J$130,"<>Yes",Checklist!$K$4:$K$130,"<>Pass",Checklist!$K$4:$K$130,"<>N/A") -> 0 | M40: =IF(E40=0,0,(G40+H40+I40+J40)/E40) -> 1 | N40: =IF(H40>0,"Fail",IF(I40>0,"Blocked",IF(G40+H40+I40+J40=0,IF(F40=0,"Optional","Not started"),IF(L40=0,"Pass","In progress")))) -> Pass
A41: Total | B41: All checks | E41: =SUM(E5:E40) -> 123 | F41: =SUM(F5:F40) -> 110 | G41: =SUM(G5:G40) -> 123 | H41: =SUM(H5:H40) -> 0 | I41: =SUM(I5:I40) -> 0 | J41: =SUM(J5:J40) -> 0 | K41: =SUM(K5:K40) -> 0 | L41: =SUM(L5:L40) -> 0 | M41: =IF(E41=0,0,(G41+H41+I41+J41)/E41) -> 1 | N41: =IF(H41>0,"Fail",IF(I41>0,"Blocked",IF(G41+H41+I41+J41=0,IF(F41=0,"Optional","Not started"),IF(L41=0,"Pass","In progress")))) -> Pass
A43: By report
A44: Report | B44: Source | E44: Items | F44: Required | G44: Pass | H44: Fail | I44: Blocked | J44: N/A | K44: Not run / empty | L44: Open (required) | M44: Done % | N44: Result
A45: #6 | B45: Report #6 round (H2, H3, N14, N18_M1, N19) and older backlog | E45: =COUNTIF(Checklist!$E$4:$E$130,$A45) -> 69 | F45: =COUNTIFS(Checklist!$E$4:$E$130,$A45,Checklist!$J$4:$J$130,"<>Yes") -> 60 | G45: =COUNTIFS(Checklist!$E$4:$E$130,$A45,Checklist!$K$4:$K$130,"Pass") -> 69 | H45: =COUNTIFS(Checklist!$E$4:$E$130,$A45,Checklist!$K$4:$K$130,"Fail") -> 0 | I45: =COUNTIFS(Checklist!$E$4:$E$130,$A45,Checklist!$K$4:$K$130,"Blocked") -> 0 | J45: =COUNTIFS(Checklist!$E$4:$E$130,$A45,Checklist!$K$4:$K$130,"N/A") -> 0 | K45: =E45-G45-H45-I45-J45 -> 0 | L45: =COUNTIFS(Checklist!$E$4:$E$130,$A45,Checklist!$J$4:$J$130,"<>Yes",Checklist!$K$4:$K$130,"<>Pass",Checklist!$K$4:$K$130,"<>N/A") -> 0 | M45: =IF(E45=0,0,(G45+H45+I45+J45)/E45) -> 1 | N45: =IF(H45>0,"Fail",IF(I45>0,"Blocked",IF(G45+H45+I45+J45=0,IF(F45=0,"Optional","Not started"),IF(L45=0,"Pass","In progress")))) -> Pass
A46: #7 | B46: Report #7 round (13 Medium tasks) | E46: =COUNTIF(Checklist!$E$4:$E$130,$A46) -> 49 | F46: =COUNTIFS(Checklist!$E$4:$E$130,$A46,Checklist!$J$4:$J$130,"<>Yes") -> 46 | G46: =COUNTIFS(Checklist!$E$4:$E$130,$A46,Checklist!$K$4:$K$130,"Pass") -> 49 | H46: =COUNTIFS(Checklist!$E$4:$E$130,$A46,Checklist!$K$4:$K$130,"Fail") -> 0 | I46: =COUNTIFS(Checklist!$E$4:$E$130,$A46,Checklist!$K$4:$K$130,"Blocked") -> 0 | J46: =COUNTIFS(Checklist!$E$4:$E$130,$A46,Checklist!$K$4:$K$130,"N/A") -> 0 | K46: =E46-G46-H46-I46-J46 -> 0 | L46: =COUNTIFS(Checklist!$E$4:$E$130,$A46,Checklist!$J$4:$J$130,"<>Yes",Checklist!$K$4:$K$130,"<>Pass",Checklist!$K$4:$K$130,"<>N/A") -> 0 | M46: =IF(E46=0,0,(G46+H46+I46+J46)/E46) -> 1 | N46: =IF(H46>0,"Fail",IF(I46>0,"Blocked",IF(G46+H46+I46+J46=0,IF(F46=0,"Optional","Not started"),IF(L46=0,"Pass","In progress")))) -> Pass
A47: #6 + #7 | B47: Player build | E47: =COUNTIF(Checklist!$E$4:$E$130,$A47) -> 5 | F47: =COUNTIFS(Checklist!$E$4:$E$130,$A47,Checklist!$J$4:$J$130,"<>Yes") -> 4 | G47: =COUNTIFS(Checklist!$E$4:$E$130,$A47,Checklist!$K$4:$K$130,"Pass") -> 5 | H47: =COUNTIFS(Checklist!$E$4:$E$130,$A47,Checklist!$K$4:$K$130,"Fail") -> 0 | I47: =COUNTIFS(Checklist!$E$4:$E$130,$A47,Checklist!$K$4:$K$130,"Blocked") -> 0 | J47: =COUNTIFS(Checklist!$E$4:$E$130,$A47,Checklist!$K$4:$K$130,"N/A") -> 0 | K47: =E47-G47-H47-I47-J47 -> 0 | L47: =COUNTIFS(Checklist!$E$4:$E$130,$A47,Checklist!$J$4:$J$130,"<>Yes",Checklist!$K$4:$K$130,"<>Pass",Checklist!$K$4:$K$130,"<>N/A") -> 0 | M47: =IF(E47=0,0,(G47+H47+I47+J47)/E47) -> 1 | N47: =IF(H47>0,"Fail",IF(I47>0,"Blocked",IF(G47+H47+I47+J47=0,IF(F47=0,"Optional","Not started"),IF(L47=0,"Pass","In progress")))) -> Pass
A49: Check: the by-report Items column must add up to the Total row (E41). Difference: | E49: =E41-SUM(E45:E47) -> 0

Sheet Temp changes
A1: Temporary changes and the revert checklist
A2: Make every change in the main project only: the ParrelSync clone shares Assets, so it gets the same change, and a revert in the main project reverts the clone too. Mark Applied when you make a change and Reverted when it's undone. Don't commit any of these.
A4: ID | B4: Used by | C4: File | D4: Temporary change | E4: Revert to (original) | F4: How to revert | G4: Applied | H4: Reverted
A5: T1 | B5: B1, B2 (20); C2 (6, optional) | C5: Assets/Prefab/GameMasterPrefab.prefab | D5: GameRules → m_startHandCards = 20 (C2: 6) | E5: 2 (C# default; the field isn't serialized in the prefab) | F5: git restore Assets/Prefab/GameMasterPrefab.prefab
A6: T2 | B6: A4 (3, optional); B1, B2 (0.05) | C6: Assets/Prefab/GameMasterPrefab.prefab | D6: Timing → m_cardDrawDelay = 0.05 (A4: 3) | E6: 0.8 | F6: git restore Assets/Prefab/GameMasterPrefab.prefab
A7: T3 | B7: B3+B4 | C7: Assets/Prefab/GameMasterPrefab.prefab | D7: GameRules → m_maxMana = 5 | E7: 20 | F7: git restore Assets/Prefab/GameMasterPrefab.prefab
A8: T4 | B8: B5 | C8: Assets/Prefab/GameMasterPrefab.prefab | D8: GameRules → m_maxHandCards = 3 | E8: 10 | F8: git restore Assets/Prefab/GameMasterPrefab.prefab
A9: T5 | B9: B2 | C9: Assets/Card/Data/Clarity.asset | D9: Rarity = UltraRare | E9: Common | F9: git restore Assets/Card/Data/Clarity.asset
A10: T6 | B10: B3+B4 | C10: Assets/Card/Data/HealingHooves.asset | D10: Activities → Element 0 → Target Type = SelfBlock (1) | E10: SelfPlayer (21) | F10: git restore Assets/Card/Data/HealingHooves.asset
A11: T7 | B11: B7 | C11: Assets/Card/Data/Iceshard.asset | D11: Activity 0 s_targetType = AnyPlayer (23) | E11: OpponentPlayer (22) | F11: git restore Assets/Card/Data/Iceshard.asset
A12: T8 | B12: B8 | C12: Assets/Card/Data/Fireball.asset | D12: Activity 0 s_targetType = RandomOpponentBlock (5) | E12: OpponentBlock (2) | F12: git restore Assets/Card/Data/Fireball.asset
A13: T9 | B13: B6 | C13: Assets/Prefab/NetworkManagerPrefab.prefab | D13: NetworkConfig → NetworkIdRecycleDelay = 1 | E13: 120 | F13: git restore Assets/Prefab/NetworkManagerPrefab.prefab
A14: T10 | B14: C1 | C14: Assets/Scripts/MultiplayerScripts/MultiplayerManager.cs:1359 | D14: First line in StartGameAfterSceneReady(): yield return new WaitForSeconds(5f); | E14: Line removed | F14: Delete the line. Use git restore on the file only if it has no other uncommitted work.
A15: T11 | B15: C2 | C15: Assets/Scripts/InGame/GameMaster/GameMaster.Spawn.cs:252, :254 | D15: Loops changed to i = 2; i < 3 and j = 2; j < 3 | E15: i = 0; i < 5 and j = 0; j < 5 | F15: Edit back, or git restore the file if it has no other uncommitted work.
A16: T12 | B16: C3 | C16: Assets/Scripts/InGame/PlayerSession.cs:167 | D16: GameMaster.Instance.HandlePlayerSurrender(this); commented out | E16: Line active | F16: Uncomment. PlayerSession.cs is also edited by T13: revert both.
A17: T13 | B17: C4 (optional) | C17: Assets/Scripts/InGame/PlayerSession.cs:286-287 | D17: Mana gate (if SelectedPlayCost() + … > m_manaCurrent.Value return false;) commented out | E17: Lines active | F17: Uncomment.
A18: T14 | B18: C5 | C18: Assets/Scripts/InGame/GameMaster/GameMaster.Card.cs:180 | D18: SendCardDataClientRpc(...) replaced by StartCoroutine(SendCardDataLater(...)); method SendCardDataLater added | E18: Original SendCardDataClientRpc line; no SendCardDataLater method | F18: Edit back, or git restore the file if it has no other uncommitted work.
A19: T15 | B19: C6 | C19: Assets/Scripts/Bootstrap.cs:167 | D19: First line in RecreateGameMaster(): throw new System.Exception("test"); | E19: Line removed | F19: Delete the line.
A20: T16 | B20: C7 (optional) | C20: Assets/Scripts/Manager/SceneFlowManager.cs:49 | D20: First line in LoadMainMenuScene(): Debug.Log("M16 check: " + …); | E20: Line removed | F20: Delete the line.
A21: — | B21: Final | C21: All files above | D21: git status shows no changes to any of these files | E21: — | F21: Let both Editors recompile afterwards.
A22: — | B22: Final | C22: Language (A19, D) | D22: Locale set to ru/ja during the checks | E22: English | F22: Main menu → Settings → English, in the Editor and in the build.
A23: — | B23: Note | C23: Assets/Fonts/MPLUSRounded1c-Medium SDF.asset | D23: May show as modified after ru/ja text renders (N28). It isn't one of the temporary changes. | E23: — | F23: Leave it for a separate decision on N28; don't count it as a leftover.
A25: Applied but not yet reverted: | D25: =COUNTIFS(G5:G23,"Yes",H5:H23,"<>Yes") -> 0 | E25: must be 0 before the player build (D) and before any commit

Sheet Known issues
A1: What you may see during the checks
A3: Known and expected: don't mark a row Fail for these
A4: You see | B4: ID | C4: Notes
A5: Cards you selected but didn't confirm last round are highlighted at the start of the next Card Selection. Cards that have left the hand are dropped from it. | B5: N26 | C5: Owner decision open: keep or clear.
A6: The warning 'Invalid mane material index.' on every pony spawn. | B6: N27 | C6: Inspector fix pending.
A7: A selection confirm pressed at the very last moment ends your Turn instead, or is lost if a respawn pause starts. | B7: N21 | C7: Latency window.
A8: After a respawn pause in your Turn, the selected board card and its confirmed target are gone; Send logs 'Send ignored: …' until you select and confirm again. | B8: N20 | C8: By design (N20 Q1). The old NRE is fixed.
A9: Send with a missing required target does nothing and logs nothing. | B9: N20 | C9: Feature gap: no UI feedback.
A10: 'Hand limit reached: your oldest card was discarded.' in long matches (hand limit 10). | B10: M15 | C10: Intended (owner decision, 2026-10-19).
A11: The lobby player item shows the short ID as the name and the full ID under it. | B11: N29 | C11: Cosmetic.
A12: The host's HUD goes blank for a moment before the result screen after a forfeit. | B12: N17 | C12: Cosmetic.
A13: NGO NetworkSceneManager.Dispose → NetworkManager.OnDestroy NullReferenceException when you stop Play Mode or quit the Editor. | B13: U9 | C13: Inside NGO, during teardown.
A14: Compiler warning CS0414 (m_cardResolveDelay). | B14: N4 | C14: The only remaining warning.
A15: 'Round preparation' still shows while cards are dealt. | B15: — | C15: Feature gap: no draw phase is set.
A16: The timer counts up (elapsed seconds), not down. | B16: L1
A17: The Space debug key (−10 HP) works in the Editor. | B17: L9 | C17: m_debugMode is on in the prefabs.
A18: Lobby or network failures appear only in the Console, with no message on screen. | B18: — | C18: Feature gap (M10 Q1, N14 Q1).
A19: MPLUSRounded1c-Medium SDF.asset shows as modified in git status after ru/ja text renders. | B19: N28 | C19: Not a temporary change; leave it for the N28 decision.
A20: A double GameScene load in a clone log. | B20: U6 | C20: Still unexplained: copy the log lines into the notes.
A22: Fixed since report #6: mark the row Fail if you see these
A23: You see | B23: ID | C23: Checked in
A24: NullReferenceException in PlayerSession.CheckPackage when you press Send. | B24: N20 | C24: A14
A25: An unhandled or 'unobserved' exception from LobbyService (e.g. GetLobbyAsync in RefreshCurrentLobby) when the match starts or the lobby refreshes. A logged, handled error is fine: copy it into the notes. | B25: M10 | C25: A20, C6
A26: Compiler warning CS0114 (PlayerUI.OnDestroy). | B26: N1 | C26: A21
A27: A respawned pony survives the lava. | B27: M3 | C27: A16, B6
A28: Errors or warnings that mention SessionManager after the second match in one Play session. | B28: M16 | C28: A21
A29: NullReferenceException when a non-host client targets an AnyPlayer card through a block. | B29: M8 | C29: B7
A30: NullReferenceException when you click a card before its data has arrived. | B30: M14 | C30: A15, C5
A31: No language option in the main menu. | B31: M12 | C31: A19, D
A32: 'Host_…', 'Client_…', 'MyLobby', 'Unknown Lobby' or an untranslated 'x / y' count in the lobby. | B32: M13 | C32: A18
A33: Founded by Owner
A34: ArgumentException: An item with the same key has already been added. Key: Team Id | C34: Falls after exiting the main Unity editor.
