Workbook

Sheet Read me
A3: About
A4: Date / baseline | B4: 2026-10-23. HEAD = 6d89a09 ('N50_N52') plus the uncommitted working tree: Codex's implementation of TASK-N54_N56_N57, TASK-N55_N58_N32 and TASK-N33_N34_N35. Line numbers are from the working tree.
A5: Sources | B5: Issue Report #13 §1–§5 (Docs/AI/Reports/2026-10-23_IssueReport-13.md), §9 of the three specs (Docs/AI/Tasks/), and Codex's report 2026-10-22_N32-N35_N54-N58_Implementation.md §6.
A6: Code review (Claude) | B6: I checked Codex's diff against each spec: it matches, with no defects (report #13 §1). • N54: the table card's text canvas no longer catches clicks. Codex's harness measured the old bug (right-hand cards: UI hit at 4 of 4 points) and the fix (0). • N57: an early Confirm Turn no longer binds the HUD half-way. • N56, N55, N58, N32: guards. N33: dead code and 2 prefabs removed. N34: 25 release log lines gated, 5 deleted. N35: HP and Life texts written only on change. Codex's release build succeeded. I didn't run Unity myself. No harness can play a real client, so this checklist is the real test.
A7: Why | B7: When this checklist passes, the three tasks can be committed and nine issues close. Section F measures N59 (the host quitting) before it is fixed, so the fix has a 'before'.
A8: Who runs it | B8: The developer: A–F and H in two Unity Editors (ParrelSync), G with a new Windows build plus an Editor. The AI agents can't run two instances.
A9: Order | B9: A → E in one or two matches (they can share matches). Then F (it ends matches on purpose). Then G (build). H at the end. I only after you commit.
A10: How to report | B10: 1. Set Status on every row of the Checklist sheet. The Summary sheet updates by itself. 2. For every Fail, paste the Console text (error plus stack trace) into 'Console output / notes'. For a visual Fail, save a screenshot and write its file name there. Clear on Play is on, so copy the Console before you press Play again. 3. Research rows (F) describe today's behavior: Pass means you saw what the row describes. If you saw something else, mark Fail and describe it. 4. If you run rows on your second machine, write 'PC 2' in Tested by. 5. New problems you notice: add them at the bottom of the Known issues sheet ('Found during the checks'). I read every sheet. 6. Tell Claude when you're done.
A12: Legend
A13: Cells to fill in | B13: Only the yellow cells on the Checklist sheet: Status, Tested by, Date, Console output / notes. Everything else is reference text or formulas.
A14: Pass | B14: Every expected result in the row was seen.
A15: Fail | B15: At least one expected result wasn't seen, or a new error appeared. Add the Console text or a screenshot name. (Typing False also counts as Fail.)
A16: Blocked | B16: The row couldn't be run (e.g. an earlier failure, the card never drawn). Say why in the notes.
A17: Not run | B17: Skipped on purpose. Fine for optional rows; for a required row it keeps the group open.
A18: N/A | B18: Doesn't apply in this setup. Counts like a Pass for the group result.
A19: Optional = Yes | B19: Optional rows don't hold back a group's Pass result.
A20: Grey text | B20: In a group's second and later rows, Check / Covers / Task / Run as / Size repeat the first row so that filtering works.
A22: Example of a filled row
A23: ID / Status | B23: A2.1 → Fail
A24: Tested by / Date | B24: Client window / 2026-10-23
A25: Console output / notes | B25: Click on the name text of the right-hand card opened nothing; the middle worked. clone-editor.log: <paste lines>. Screenshot: A2-1_client.png.
A27: Preparation
A28: 1. The clone with its own log | B28: Close the clone Editor if it's open. Then start it from PowerShell, so that it writes its own log: & 'C:\Program Files\Unity\Hub\Editor\6000.3.13f1\Editor\Unity.exe' -projectPath 'C:\Lesson\FallenStar-Spellcasters_clone_1' -logFile 'C:\Lesson\clone-editor.log' Open the main project as usual. The clone shares Assets, so it runs the same code.
A29: 2. Console | B29: In both Editors, open the Console: Collapse off, Clear on Play on.
A30: 3. Clean start | B30: Both Editors are in English. git status may show the font asset as modified: that's fine during the checks (see 'Before you commit').
A31: 4. Start a match | B31: Log in and go to the Lobby in both windows. The main Editor presses Create Lobby: from now on it's the host window. The clone presses Find Lobby, selects the lobby and presses Join: it's the client window. The host presses Start game.
A32: 5. Game view | B32: 1920×1080 in both Editors is enough this time (no layout checks).
A33: 6. Phase log | B33: The Editors keep their debug logs on purpose (only release builds are quiet). The host Console logs every phase: 'Round break phase started', 'DrawPhase started', 'Card selection phase started.', 'Player Action phase started', 'Waiting for Respawn', 'GameMaster: match ended …'.
A35: Useful facts
A36: Table sides | B36: Both windows look at the table from the same camera. The HOST's cards, pony and blocks are always on the LEFT (red side); the CLIENT's are on the RIGHT (blue side). The old bug (N54) hit only the right-hand cards, in both windows.
A37: The big card | B37: Left-clicking a card on the table, or hovering a card in the bottom row, shows the card large at the left edge. It never takes clicks. It hides on the next world click or when the pointer leaves the row.
A38: Casting | B38: In your Player action: left-click the played card in the BOTTOM HUD ROW → click the target on the table → Confirm → Send. Clicking a table card only shows its big card; it doesn't pick it for casting. Self cards (Healing Hooves, Clarity) choose their target automatically.
A39: The bottom row | B39: In Card Selection it shows your hand. In Player action it shows the cards you played this round.
A40: Phases (en) | B40: Line 1 of the announcer: 'Round preparation' (5 s; it still shows while cards are dealt), 'Card Selection' (60 s), 'Player action' (60 s per player), 'Waiting for respawn' (30 s).
A41: Turn order | B41: The player whose selected cards (play and discard) cost more goes first.
A42: Controls | B42: Hand cards: left-click = play, right-click = discard. Confirm Turn confirms the selection in Card Selection, ends your Player action, and confirms the respawn block in Waiting for respawn. W/A/S/D = one step (own Player action). Space = −10 HP to yourself (own Player action; Editor and development builds only).
A43: Cards (en / ru) | B43: Ice Shard / Ледяной осколок: 2 mana, 20 damage to the opponent's pony. Fireball / Огненный шар: 3 mana, 50 damage to an opponent block. Clarity / Ясность: 3 mana, draw 2. Healing Hooves / Исцеляющие копыта: 4 mana, heal yourself 30.
A44: Numbers | B44: Pony HP 100, block HP 100, 3 lives, 25 blocks per player. Mana 2 → 4 → 6 … up to 20. 2 new cards per player per round. Hand limit 10.
A45: HUD texts | B45: en 'HP : 100' / 'Life : 3'; ru 'ХП : 100' / 'Жизни : 3'; ja 'HP : 100' / 'ライフ : 3'. When a player is out of lives: 'Player Dead' / 'Игрок погиб' / 'プレイヤー死亡'.
A46: Result texts (en) | B46: Titles: 'Victory!', 'Defeat', 'Draw'. Reasons: 'Your opponent left the match.', 'You left the match.', 'Your opponent lost all their lives.', 'You lost all your lives.', 'Both players lost all their lives.'
...

Sheet Checklist
A1: QA checklist: N54–N58, N32–N35 and N59 research (Issue Report #13)
A2: Baseline 6d89a09 plus the working tree (2026-10-23). Fill in only the yellow cells. Research rows (F) describe today's behavior: Pass = you saw it.
A3: ID | B3: Group | C3: Check | D3: Covers | E3: Task | F3: Run as | G3: Size | H3: Steps | I3: Expected result | J3: Optional | K3: Status | L3: Tested by | M3: Date | N3: Console output / notes
A4: A. Table-card clicks: both sides in both windows. Two Editors; main = host, clone = client.
A5: A1.1 | B5: A1 | C5: Host window: clicking table cards opens the big card | D5: N54 | E5: N54_N56_N57 | F5: Host | G5: 1920×1080 | H5: Start a match (Read me → Preparation 4). Both players select 1–2 cards to play and press Confirm Turn. When 'Player action' starts, the played cards lie on the table: the host's on the LEFT, the client's on the RIGHT. In the HOST window, left-click the middle of each LEFT-hand card. | I5: Each click shows that card as the big card at the left edge of the screen. | K5: Pass | L5: Owner | M5: 46318
A6: A1.2 | B6: A1 | C6: Host window: clicking table cards opens the big card | D6: N54 | E6: N54_N56_N57 | F6: Host | G6: 1920×1080 | H6: Still in the host window, left-click each RIGHT-hand (client's) card three times: on its middle, on its name text, on its picture. | I6: Every click shows that card's big card. (Before the fix nothing opened here: N54.) | K6: Pass | L6: Owner | M6: 46318
A7: A2.1 | B7: A2 | C7: Client window: clicking table cards opens the big card | D7: N54 | E7: N54_N56_N57 | F7: Client | G7: 1920×1080 | H7: In the CLIENT window, the same three clicks (middle, name text, picture) on each RIGHT-hand card: the client's own cards. | I7: Every click shows the big card. This is last round's failed A2.1. | K7: Pass | L7: Owner | M7: 46318
A8: A2.2 | B8: A2 | C8: Client window: clicking table cards opens the big card | D8: N54 | E8: N54_N56_N57 | F8: Client | G8: 1920×1080 | H8: In the client window, left-click the middle of each LEFT-hand (host's) card. | I8: Each click shows the big card. | K8: Pass | L8: Owner | M8: 46318
A9: A3.1 | B9: A3 | C9: The table looks and behaves as before | D9: N54 | E9: N54_N56_N57 | F9: Both | G9: 1920×1080 | H9: Look at the table cards on both sides, in both windows. | I9: Name, cost and description render on the cards as in the last round: nothing missing or newly mirrored, no flicker. | K9: Pass | L9: Owner | M9: 46318
A10: A3.2 | B10: A3 | C10: The table looks and behaves as before | D10: N54 | E10: N54_N56_N57 | F10: Both | G10: 1920×1080 | H10: With a big card shown, left-click empty ground or the sky. | I10: The big card disappears. | K10: Pass | L10: Owner | M10: 46318
A11: A3.3 | B11: A3 | C11: The table looks and behaves as before | D11: N54 | E11: N54_N56_N57 | F11: Both | G11: 1920×1080 | H11: In a later round's Player action (new cards on the table), repeat one right-hand click in each window. | I11: Still opens the big card. | J11: Yes | K11: Pass | L11: Owner | M11: 46318
A12: B. Casting through the HUD row; Confirm and Send. Two Editors.
A13: B1.1 | B13: B1 | C13: Casting still works, for both players | D13: N54, N58, N32 | E13: N55_N58_N32 | F13: Both | G13: 1920×1080 | H13: In the CLIENT's own Player action: left-click a played Ice Shard (or Fireball) in the bottom HUD row → left-click its target on the table (Ice Shard: the host's pony; Fireball: one of the host's blocks) → Confirm → Send. | I13: The effect shows in both windows: the host's pony loses 20 HP (or the block 50 HP). The host Console has no 'Card package rejected. Invalid target count' warning. | K13: Pass | L13: Owner | M13: 46318
A14: B1.2 | B14: B1 | C14: Casting still works, for both players | D14: N54, N58, N32 | E14: N55_N58_N32 | F14: Both | G14: 1920×1080 | H14: The same in the HOST's own Player action, at the client's pony or block. | I14: The effect shows in both windows; no 'Card package rejected' warning. | K14: Pass | L14: Owner | M14: 46318
A15: B1.3 | B15: B1 | C15: Casting still works, for both players | D15: N54, N58, N32 | E15: N55_N58_N32 | F15: Both | G15: 1920×1080 | H15: Play Healing Hooves or Clarity: pick it in the HUD row → Confirm → Send (the target is chosen automatically). | I15: Healing Hooves: your HP rises by up to 30 (max 100). Clarity: your hand has 2 more cards at the next Card Selection. | K15: Pass | L15: Owner | M15: 46318
A16: B1.4 | B16: B1 | C16: Casting still works, for both players | D16: N54, N58, N32 | E16: N55_N58_N32 | F16: Both | G16: 1920×1080 | H16: Click hand cards in the bottom row, and the Confirm / Send / Confirm Turn buttons, at places where table objects (cards, blocks, ponies) lie behind them on screen. | I16: Only the HUD reacts. No table object gets selected and no big card opens from the table behind the HUD. | K16: Pass | L16: Owner | M16: 46318
A17: B2.1 | B17: B2 | C17: Confirm and Send at odd moments | D17: N56 | E17: N54_N56_N57 | F17: Both | G17: 1920×1080 | H17: In your own Player action, press Confirm and then Send without picking a card. | I17: Only the known warnings 'No card selected for control package.' and 'Send ignored: no card target was confirmed.' No exception. | K17: Pass | L17: Owner | M17: 46318
A18: B2.2 | B18: B2 | C18: Confirm and Send at odd moments | D18: N56 | E18: N54_N56_N57 | F18: Both | G18: 1920×1080 | H18: Start a new match. Right after the client's match screen appears (before the first banner), press Confirm and Send a few times in the client window. | I18: No NullReferenceException. At most one 'ConfirmSelect ignored …' or 'TryConfirmSend ignored …' warning per press, or nothing. | J18: Yes | K18: Pass | L18: Owner | M18: 46318
A19: C. Confirm Turn pressed before the match starts. Two Editors.
A20: C1.1 | B20: C1 | C20: An early Confirm Turn doesn't break the hand row | D20: N57 | E20: N54_N56_N57 | F20: Host | G20: 1920×1080 | H20: Start a new match. In the HOST window, as soon as the match screen (HUD) appears and before the first banner 'Round preparation', press Confirm Turn 3–5 times quickly. | I20: No error in the Console. When Card Selection starts, the host's bottom row shows the dealt hand as usual, and cards can be selected. (If the banner came before you could click, mark Blocked: G1.3 repeats this with the build as host, where the window is longer.) | K20: Pass | L20: Owner | M20: 46318
A21: C1.2 | B21: C1 | C21: An early Confirm Turn doesn't break the hand row | D21: N57 | E21: N54_N56_N57 | F21: Host | G21: 1920×1080 | H21: Play on for at least two more rounds. | I21: Every Card Selection shows the hand; every Player action shows your played cards. (N57's symptom was an empty row for the whole match.) | K21: Pass | L21: Owner | M21: 46318
A22: C1.3 | B22: C1 | C22: An early Confirm Turn doesn't break the hand row | D22: N57 | E22: N54_N56_N57 | F22: Host | G22: 1920×1080 | H22: Same quick Confirm Turn presses in the CLIENT window right after its match screen appears, then play two rounds. | I22: As C1.1 and C1.2, for the client. | J22: Yes | K22: Pass | L22: Owner | M22: 46318
A23: D. HP and Life texts. Two Editors.
A24: D1.1 | B24: D1 | C24: HP and Life update at once | D24: N35 | E24: N33_N34_N35 | F24: Both | G24: 1920×1080 | H24: Damage a pony: cast Ice Shard at the opponent, or press Space in your own Player action (−10 HP to yourself). | I24: The damaged player's HUD 'HP : …' changes at once to the new value. 'Life : …' stays. | K24: Pass | L24: Owner | M24: 46318
A25: D1.2 | B25: D1 | C25: HP and Life update at once | D25: N35 | E25: N33_N34_N35 | F25: Both | G25: 1920×1080 | H25: Kill a pony (Read me → Useful facts), then confirm a respawn block in 'Waiting for respawn'. | I25: 'Life' drops by 1 at once. During the respawn wait HP and Life keep their last values (known). After the respawn: 'HP : 100'. | K25: Pass | L25: Owner | M25: 46318
A26: D1.3 | B26: D1 | C26: HP and Life update at once | D26: N35 | E26: N33_N34_N35 | F26: Both | G26: 1920×1080 | H26: While alive, switch the language en → ru → ja → en (Read me → Switch language). Watch both windows. | I26: HP and Life change language at once (ru 'ХП : …' / 'Жизни : …', ja 'HP : …' / 'ライフ : …'); the numbers stay the same. | K26: Pass | L26: Owner | M26: 46318
A27: D1.4 | B27: D1 | C27: HP and Life update at once | D27: N35 | E27: N33_N34_N35 | F27: Both | G27: 1920×1080 | H27: Switch the language once during 'Waiting for respawn'. | I27: HP and Life may keep the old language until the respawn, then switch (known, unchanged by N35). | J27: Yes | K27: Pass | L27: Owner | M27: 46318
A28: D1.5 | B28: D1 | C28: HP and Life update at once | D28: N35 | E28: N33_N34_N35 | F28: Both | G28: 1920×1080 | H28: Kill the same pony until its lives run out. | I28: Just before the Result screen, that player's HUD may briefly show 'Player Dead' with an empty Life text. Both windows then show the Result screen. | J28: Yes | K28: Pass | L28: Owner | M28: 46318
A29: E. Lobby, a full match, a second match. Two Editors.
A30: E1.1 | B30: E1 | C30: Lobby and match flow after the dead-code removal | D30: N33, N34, N55 | E30: N33_N34_N35 | F30: Both | G30: 1920×1080 | H30: Before the host creates a lobby, press Find Lobby / Refresh Lobby in the clone 2–3 times. Then the host creates one; refresh again and join. | I30: First 'Lobby not found', then the host's lobby is listed and can be joined. No errors. | K30: Pass | L30: Owner | M30: 46318
A31: E1.2 | B31: E1 | C31: Lobby and match flow after the dead-code removal | D31: N33, N34, N55 | E31: N33_N34_N35 | F31: Both | G31: 1920×1080 | H31: Play a match to the end (one player runs out of lives). | I31: Both windows show the Result screen: 'Victory!' / 'Defeat' with 'Your opponent lost all their lives.' / 'You lost all your lives.' Main menu works. | K31: Pass | L31: Owner | M31: 46318
A32: E1.3 | B32: E1 | C32: Lobby and match flow after the dead-code removal | D32: N33, N34, N55 | E32: N33_N34_N35 | F32: Both | G32: 1920×1080 | H32: From the main menu, create, join and start a second match without restarting the Editors. | I32: The second match starts normally: ponies, blocks, hands and phases. | K32: Pass | L32: Owner | M32: 46318
A33: F. QA research: leaving and quitting mid-match (N59). Expected = today's behavior. Two Editors.
A34: F1.1 | B34: F1 | C34: Leave and quit, both directions | D34: N59, H6, N19 | E34: Research | F34: Both | G34: 1920×1080 | H34: Mid-match, the CLIENT presses Leave match → Leave. | I34: Client: 'Defeat' / 'You left the match.' Host: 'Victory!' / 'Your opponent left the match.' | K34: Pass | L34: Owner | M34: 46318
A35: F1.2 | B35: F1 | C35: Leave and quit, both directions | D35: N59, H6, N19 | E35: Research | F35: Both | G35: 1920×1080 | H35: Start a new match. Mid-match, stop Play Mode in the CLIENT (clone) Editor. | I35: Host: 'Victory!' / 'Your opponent left the match.' (your note from 2026-10-22). | K35: Pass | L35: Owner | M35: 46318
A36: F1.3 | B36: F1 | C36: Leave and quit, both directions | D36: N59, H6, N19 | E36: Research | F36: Both | G36: 1920×1080 | H36: Start a new match. Mid-match, stop Play Mode in the HOST (main) Editor. Watch the clone. | I36: N59, known: the client goes back to the Lobby screen with no Result screen and no message. Paste any clone Console lines into the notes. | K36: Pass | L36: Owner | M36: 46318
A37: F1.4 | B37: F1 | C37: Leave and quit, both directions | D37: N59, H6, N19 | E37: Research | F37: Both | G37: 1920×1080 | H37: Start a new match. Mid-match, the HOST presses Leave match → Leave. | I37: Host: 'Defeat' / 'You left the match.' Client: 'Victory!' / 'Your opponent left the match.' | J37: Yes | K37: Pass | L37: Owner | M37: 46318
A38: F1.5 | B38: F1 | C38: Leave and quit, both directions | D38: N59, H6, N19 | E38: Research | F38: Both | G38: 1920×1080 | H38: Right after F1.3, on the client press Refresh Lobby twice, about 30 s apart. | I38: The dead host's lobby isn't listed. If it is, press Join once and note what happens. | J38: Yes | K38: Pass | L38: Owner | M38: 46318
A39: G. A new release build against an Editor.
A40: G1.1 | B40: G1 | C40: Release build: match, early Confirm, quiet Player.log | D40: N34, N33, N57 | E40: N33_N34_N35 | F40: Build + Editor | G40: Any | H40: In the main Editor: File → Build Profiles → Windows, Development Build OFF → Build to C:\Lesson\Spellcasters.Build (replace the old build). | I40: The build succeeds. | K40: Pass | L40: Owner | M40: 46318
...

Sheet Summary
A1: Results summary
A2: Calculated from the Checklist sheet; don't edit. Result: Fail if any row failed; Blocked if any row is blocked; Pass when every required row is Pass or N/A.
A4: Group | B4: Check | C4: Covers | D4: Task | E4: Items | F4: Required | G4: Pass | H4: Fail | I4: Blocked | J4: N/A | K4: Not run / empty | L4: Open (required) | M4: Done % | N4: Result
A5: A1 | B5: Host window: clicking table cards opens the big card | C5: N54 | D5: N54_N56_N57 | E5: =COUNTIF(Checklist!$B$4:$B$52,$A5) -> 2 | F5: =COUNTIFS(Checklist!$B$4:$B$52,$A5,Checklist!$J$4:$J$52,"<>Yes") -> 2 | G5: =COUNTIFS(Checklist!$B$4:$B$52,$A5,Checklist!$K$4:$K$52,"Pass") -> 2 | H5: =COUNTIFS(Checklist!$B$4:$B$52,$A5,Checklist!$K$4:$K$52,"Fail")+COUNTIFS(Checklist!$B$4:$B$52,$A5,Checklist!$K$4:$K$52,FALSE) -> 0 | I5: =COUNTIFS(Checklist!$B$4:$B$52,$A5,Checklist!$K$4:$K$52,"Blocked") -> 0 | J5: =COUNTIFS(Checklist!$B$4:$B$52,$A5,Checklist!$K$4:$K$52,"N/A") -> 0 | K5: =E5-G5-H5-I5-J5 -> 0 | L5: =F5-COUNTIFS(Checklist!$B$4:$B$52,$A5,Checklist!$J$4:$J$52,"<>Yes",Checklist!$K$4:$K$52,"Pass")-COUNTIFS(Checklist!$B$4:$B$52,$A5,Checklist!$J$4:$J$52,"<>Yes",Checklist!$K$4:$K$52,"N/A") -> 0 | M5: =IF(E5=0,0,(G5+H5+I5+J5)/E5) -> 1 | N5: =IF(H5>0,"Fail",IF(I5>0,"Blocked",IF(L5=0,IF(F5=0,IF(G5+J5=0,"Optional","Pass"),"Pass"),IF(G5+J5=0,"Not started","In progress")))) -> Pass
A6: A2 | B6: Client window: clicking table cards opens the big card | C6: N54 | D6: N54_N56_N57 | E6: =COUNTIF(Checklist!$B$4:$B$52,$A6) -> 2 | F6: =COUNTIFS(Checklist!$B$4:$B$52,$A6,Checklist!$J$4:$J$52,"<>Yes") -> 2 | G6: =COUNTIFS(Checklist!$B$4:$B$52,$A6,Checklist!$K$4:$K$52,"Pass") -> 2 | H6: =COUNTIFS(Checklist!$B$4:$B$52,$A6,Checklist!$K$4:$K$52,"Fail")+COUNTIFS(Checklist!$B$4:$B$52,$A6,Checklist!$K$4:$K$52,FALSE) -> 0 | I6: =COUNTIFS(Checklist!$B$4:$B$52,$A6,Checklist!$K$4:$K$52,"Blocked") -> 0 | J6: =COUNTIFS(Checklist!$B$4:$B$52,$A6,Checklist!$K$4:$K$52,"N/A") -> 0 | K6: =E6-G6-H6-I6-J6 -> 0 | L6: =F6-COUNTIFS(Checklist!$B$4:$B$52,$A6,Checklist!$J$4:$J$52,"<>Yes",Checklist!$K$4:$K$52,"Pass")-COUNTIFS(Checklist!$B$4:$B$52,$A6,Checklist!$J$4:$J$52,"<>Yes",Checklist!$K$4:$K$52,"N/A") -> 0 | M6: =IF(E6=0,0,(G6+H6+I6+J6)/E6) -> 1 | N6: =IF(H6>0,"Fail",IF(I6>0,"Blocked",IF(L6=0,IF(F6=0,IF(G6+J6=0,"Optional","Pass"),"Pass"),IF(G6+J6=0,"Not started","In progress")))) -> Pass
A7: A3 | B7: The table looks and behaves as before | C7: N54 | D7: N54_N56_N57 | E7: =COUNTIF(Checklist!$B$4:$B$52,$A7) -> 3 | F7: =COUNTIFS(Checklist!$B$4:$B$52,$A7,Checklist!$J$4:$J$52,"<>Yes") -> 2 | G7: =COUNTIFS(Checklist!$B$4:$B$52,$A7,Checklist!$K$4:$K$52,"Pass") -> 3 | H7: =COUNTIFS(Checklist!$B$4:$B$52,$A7,Checklist!$K$4:$K$52,"Fail")+COUNTIFS(Checklist!$B$4:$B$52,$A7,Checklist!$K$4:$K$52,FALSE) -> 0 | I7: =COUNTIFS(Checklist!$B$4:$B$52,$A7,Checklist!$K$4:$K$52,"Blocked") -> 0 | J7: =COUNTIFS(Checklist!$B$4:$B$52,$A7,Checklist!$K$4:$K$52,"N/A") -> 0 | K7: =E7-G7-H7-I7-J7 -> 0 | L7: =F7-COUNTIFS(Checklist!$B$4:$B$52,$A7,Checklist!$J$4:$J$52,"<>Yes",Checklist!$K$4:$K$52,"Pass")-COUNTIFS(Checklist!$B$4:$B$52,$A7,Checklist!$J$4:$J$52,"<>Yes",Checklist!$K$4:$K$52,"N/A") -> 0 | M7: =IF(E7=0,0,(G7+H7+I7+J7)/E7) -> 1 | N7: =IF(H7>0,"Fail",IF(I7>0,"Blocked",IF(L7=0,IF(F7=0,IF(G7+J7=0,"Optional","Pass"),"Pass"),IF(G7+J7=0,"Not started","In progress")))) -> Pass
A8: B1 | B8: Casting still works, for both players | C8: N54, N58, N32 | D8: N55_N58_N32 | E8: =COUNTIF(Checklist!$B$4:$B$52,$A8) -> 4 | F8: =COUNTIFS(Checklist!$B$4:$B$52,$A8,Checklist!$J$4:$J$52,"<>Yes") -> 4 | G8: =COUNTIFS(Checklist!$B$4:$B$52,$A8,Checklist!$K$4:$K$52,"Pass") -> 4 | H8: =COUNTIFS(Checklist!$B$4:$B$52,$A8,Checklist!$K$4:$K$52,"Fail")+COUNTIFS(Checklist!$B$4:$B$52,$A8,Checklist!$K$4:$K$52,FALSE) -> 0 | I8: =COUNTIFS(Checklist!$B$4:$B$52,$A8,Checklist!$K$4:$K$52,"Blocked") -> 0 | J8: =COUNTIFS(Checklist!$B$4:$B$52,$A8,Checklist!$K$4:$K$52,"N/A") -> 0 | K8: =E8-G8-H8-I8-J8 -> 0 | L8: =F8-COUNTIFS(Checklist!$B$4:$B$52,$A8,Checklist!$J$4:$J$52,"<>Yes",Checklist!$K$4:$K$52,"Pass")-COUNTIFS(Checklist!$B$4:$B$52,$A8,Checklist!$J$4:$J$52,"<>Yes",Checklist!$K$4:$K$52,"N/A") -> 0 | M8: =IF(E8=0,0,(G8+H8+I8+J8)/E8) -> 1 | N8: =IF(H8>0,"Fail",IF(I8>0,"Blocked",IF(L8=0,IF(F8=0,IF(G8+J8=0,"Optional","Pass"),"Pass"),IF(G8+J8=0,"Not started","In progress")))) -> Pass
A9: B2 | B9: Confirm and Send at odd moments | C9: N56 | D9: N54_N56_N57 | E9: =COUNTIF(Checklist!$B$4:$B$52,$A9) -> 2 | F9: =COUNTIFS(Checklist!$B$4:$B$52,$A9,Checklist!$J$4:$J$52,"<>Yes") -> 1 | G9: =COUNTIFS(Checklist!$B$4:$B$52,$A9,Checklist!$K$4:$K$52,"Pass") -> 2 | H9: =COUNTIFS(Checklist!$B$4:$B$52,$A9,Checklist!$K$4:$K$52,"Fail")+COUNTIFS(Checklist!$B$4:$B$52,$A9,Checklist!$K$4:$K$52,FALSE) -> 0 | I9: =COUNTIFS(Checklist!$B$4:$B$52,$A9,Checklist!$K$4:$K$52,"Blocked") -> 0 | J9: =COUNTIFS(Checklist!$B$4:$B$52,$A9,Checklist!$K$4:$K$52,"N/A") -> 0 | K9: =E9-G9-H9-I9-J9 -> 0 | L9: =F9-COUNTIFS(Checklist!$B$4:$B$52,$A9,Checklist!$J$4:$J$52,"<>Yes",Checklist!$K$4:$K$52,"Pass")-COUNTIFS(Checklist!$B$4:$B$52,$A9,Checklist!$J$4:$J$52,"<>Yes",Checklist!$K$4:$K$52,"N/A") -> 0 | M9: =IF(E9=0,0,(G9+H9+I9+J9)/E9) -> 1 | N9: =IF(H9>0,"Fail",IF(I9>0,"Blocked",IF(L9=0,IF(F9=0,IF(G9+J9=0,"Optional","Pass"),"Pass"),IF(G9+J9=0,"Not started","In progress")))) -> Pass
A10: C1 | B10: An early Confirm Turn doesn't break the hand row | C10: N57 | D10: N54_N56_N57 | E10: =COUNTIF(Checklist!$B$4:$B$52,$A10) -> 3 | F10: =COUNTIFS(Checklist!$B$4:$B$52,$A10,Checklist!$J$4:$J$52,"<>Yes") -> 2 | G10: =COUNTIFS(Checklist!$B$4:$B$52,$A10,Checklist!$K$4:$K$52,"Pass") -> 3 | H10: =COUNTIFS(Checklist!$B$4:$B$52,$A10,Checklist!$K$4:$K$52,"Fail")+COUNTIFS(Checklist!$B$4:$B$52,$A10,Checklist!$K$4:$K$52,FALSE) -> 0 | I10: =COUNTIFS(Checklist!$B$4:$B$52,$A10,Checklist!$K$4:$K$52,"Blocked") -> 0 | J10: =COUNTIFS(Checklist!$B$4:$B$52,$A10,Checklist!$K$4:$K$52,"N/A") -> 0 | K10: =E10-G10-H10-I10-J10 -> 0 | L10: =F10-COUNTIFS(Checklist!$B$4:$B$52,$A10,Checklist!$J$4:$J$52,"<>Yes",Checklist!$K$4:$K$52,"Pass")-COUNTIFS(Checklist!$B$4:$B$52,$A10,Checklist!$J$4:$J$52,"<>Yes",Checklist!$K$4:$K$52,"N/A") -> 0 | M10: =IF(E10=0,0,(G10+H10+I10+J10)/E10) -> 1 | N10: =IF(H10>0,"Fail",IF(I10>0,"Blocked",IF(L10=0,IF(F10=0,IF(G10+J10=0,"Optional","Pass"),"Pass"),IF(G10+J10=0,"Not started","In progress")))) -> Pass
A11: D1 | B11: HP and Life update at once | C11: N35 | D11: N33_N34_N35 | E11: =COUNTIF(Checklist!$B$4:$B$52,$A11) -> 5 | F11: =COUNTIFS(Checklist!$B$4:$B$52,$A11,Checklist!$J$4:$J$52,"<>Yes") -> 3 | G11: =COUNTIFS(Checklist!$B$4:$B$52,$A11,Checklist!$K$4:$K$52,"Pass") -> 5 | H11: =COUNTIFS(Checklist!$B$4:$B$52,$A11,Checklist!$K$4:$K$52,"Fail")+COUNTIFS(Checklist!$B$4:$B$52,$A11,Checklist!$K$4:$K$52,FALSE) -> 0 | I11: =COUNTIFS(Checklist!$B$4:$B$52,$A11,Checklist!$K$4:$K$52,"Blocked") -> 0 | J11: =COUNTIFS(Checklist!$B$4:$B$52,$A11,Checklist!$K$4:$K$52,"N/A") -> 0 | K11: =E11-G11-H11-I11-J11 -> 0 | L11: =F11-COUNTIFS(Checklist!$B$4:$B$52,$A11,Checklist!$J$4:$J$52,"<>Yes",Checklist!$K$4:$K$52,"Pass")-COUNTIFS(Checklist!$B$4:$B$52,$A11,Checklist!$J$4:$J$52,"<>Yes",Checklist!$K$4:$K$52,"N/A") -> 0 | M11: =IF(E11=0,0,(G11+H11+I11+J11)/E11) -> 1 | N11: =IF(H11>0,"Fail",IF(I11>0,"Blocked",IF(L11=0,IF(F11=0,IF(G11+J11=0,"Optional","Pass"),"Pass"),IF(G11+J11=0,"Not started","In progress")))) -> Pass
A12: E1 | B12: Lobby and match flow after the dead-code removal | C12: N33, N34, N55 | D12: N33_N34_N35 | E12: =COUNTIF(Checklist!$B$4:$B$52,$A12) -> 3 | F12: =COUNTIFS(Checklist!$B$4:$B$52,$A12,Checklist!$J$4:$J$52,"<>Yes") -> 3 | G12: =COUNTIFS(Checklist!$B$4:$B$52,$A12,Checklist!$K$4:$K$52,"Pass") -> 3 | H12: =COUNTIFS(Checklist!$B$4:$B$52,$A12,Checklist!$K$4:$K$52,"Fail")+COUNTIFS(Checklist!$B$4:$B$52,$A12,Checklist!$K$4:$K$52,FALSE) -> 0 | I12: =COUNTIFS(Checklist!$B$4:$B$52,$A12,Checklist!$K$4:$K$52,"Blocked") -> 0 | J12: =COUNTIFS(Checklist!$B$4:$B$52,$A12,Checklist!$K$4:$K$52,"N/A") -> 0 | K12: =E12-G12-H12-I12-J12 -> 0 | L12: =F12-COUNTIFS(Checklist!$B$4:$B$52,$A12,Checklist!$J$4:$J$52,"<>Yes",Checklist!$K$4:$K$52,"Pass")-COUNTIFS(Checklist!$B$4:$B$52,$A12,Checklist!$J$4:$J$52,"<>Yes",Checklist!$K$4:$K$52,"N/A") -> 0 | M12: =IF(E12=0,0,(G12+H12+I12+J12)/E12) -> 1 | N12: =IF(H12>0,"Fail",IF(I12>0,"Blocked",IF(L12=0,IF(F12=0,IF(G12+J12=0,"Optional","Pass"),"Pass"),IF(G12+J12=0,"Not started","In progress")))) -> Pass
A13: F1 | B13: Leave and quit, both directions | C13: N59, H6, N19 | D13: Research | E13: =COUNTIF(Checklist!$B$4:$B$52,$A13) -> 5 | F13: =COUNTIFS(Checklist!$B$4:$B$52,$A13,Checklist!$J$4:$J$52,"<>Yes") -> 3 | G13: =COUNTIFS(Checklist!$B$4:$B$52,$A13,Checklist!$K$4:$K$52,"Pass") -> 5 | H13: =COUNTIFS(Checklist!$B$4:$B$52,$A13,Checklist!$K$4:$K$52,"Fail")+COUNTIFS(Checklist!$B$4:$B$52,$A13,Checklist!$K$4:$K$52,FALSE) -> 0 | I13: =COUNTIFS(Checklist!$B$4:$B$52,$A13,Checklist!$K$4:$K$52,"Blocked") -> 0 | J13: =COUNTIFS(Checklist!$B$4:$B$52,$A13,Checklist!$K$4:$K$52,"N/A") -> 0 | K13: =E13-G13-H13-I13-J13 -> 0 | L13: =F13-COUNTIFS(Checklist!$B$4:$B$52,$A13,Checklist!$J$4:$J$52,"<>Yes",Checklist!$K$4:$K$52,"Pass")-COUNTIFS(Checklist!$B$4:$B$52,$A13,Checklist!$J$4:$J$52,"<>Yes",Checklist!$K$4:$K$52,"N/A") -> 0 | M13: =IF(E13=0,0,(G13+H13+I13+J13)/E13) -> 1 | N13: =IF(H13>0,"Fail",IF(I13>0,"Blocked",IF(L13=0,IF(F13=0,IF(G13+J13=0,"Optional","Pass"),"Pass"),IF(G13+J13=0,"Not started","In progress")))) -> Pass
A14: G1 | B14: Release build: match, early Confirm, quiet Player.log | C14: N34, N33, N57 | D14: N33_N34_N35 | E14: =COUNTIF(Checklist!$B$4:$B$52,$A14) -> 6 | F14: =COUNTIFS(Checklist!$B$4:$B$52,$A14,Checklist!$J$4:$J$52,"<>Yes") -> 5 | G14: =COUNTIFS(Checklist!$B$4:$B$52,$A14,Checklist!$K$4:$K$52,"Pass") -> 6 | H14: =COUNTIFS(Checklist!$B$4:$B$52,$A14,Checklist!$K$4:$K$52,"Fail")+COUNTIFS(Checklist!$B$4:$B$52,$A14,Checklist!$K$4:$K$52,FALSE) -> 0 | I14: =COUNTIFS(Checklist!$B$4:$B$52,$A14,Checklist!$K$4:$K$52,"Blocked") -> 0 | J14: =COUNTIFS(Checklist!$B$4:$B$52,$A14,Checklist!$K$4:$K$52,"N/A") -> 0 | K14: =E14-G14-H14-I14-J14 -> 0 | L14: =F14-COUNTIFS(Checklist!$B$4:$B$52,$A14,Checklist!$J$4:$J$52,"<>Yes",Checklist!$K$4:$K$52,"Pass")-COUNTIFS(Checklist!$B$4:$B$52,$A14,Checklist!$J$4:$J$52,"<>Yes",Checklist!$K$4:$K$52,"N/A") -> 0 | M14: =IF(E14=0,0,(G14+H14+I14+J14)/E14) -> 1 | N14: =IF(H14>0,"Fail",IF(I14>0,"Blocked",IF(L14=0,IF(F14=0,IF(G14+J14=0,"Optional","Pass"),"Pass"),IF(G14+J14=0,"Not started","In progress")))) -> Pass
A15: H1 | B15: Editor logs are clean | C15: All | D15: — | E15: =COUNTIF(Checklist!$B$4:$B$52,$A15) -> 3 | F15: =COUNTIFS(Checklist!$B$4:$B$52,$A15,Checklist!$J$4:$J$52,"<>Yes") -> 2 | G15: =COUNTIFS(Checklist!$B$4:$B$52,$A15,Checklist!$K$4:$K$52,"Pass") -> 3 | H15: =COUNTIFS(Checklist!$B$4:$B$52,$A15,Checklist!$K$4:$K$52,"Fail")+COUNTIFS(Checklist!$B$4:$B$52,$A15,Checklist!$K$4:$K$52,FALSE) -> 0 | I15: =COUNTIFS(Checklist!$B$4:$B$52,$A15,Checklist!$K$4:$K$52,"Blocked") -> 0 | J15: =COUNTIFS(Checklist!$B$4:$B$52,$A15,Checklist!$K$4:$K$52,"N/A") -> 0 | K15: =E15-G15-H15-I15-J15 -> 0 | L15: =F15-COUNTIFS(Checklist!$B$4:$B$52,$A15,Checklist!$J$4:$J$52,"<>Yes",Checklist!$K$4:$K$52,"Pass")-COUNTIFS(Checklist!$B$4:$B$52,$A15,Checklist!$J$4:$J$52,"<>Yes",Checklist!$K$4:$K$52,"N/A") -> 0 | M15: =IF(E15=0,0,(G15+H15+I15+J15)/E15) -> 1 | N15: =IF(H15>0,"Fail",IF(I15>0,"Blocked",IF(L15=0,IF(F15=0,IF(G15+J15=0,"Optional","Pass"),"Pass"),IF(G15+J15=0,"Not started","In progress")))) -> Pass
A16: I1 | B16: A missing spawn point aborts the start cleanly | C16: N55 | D16: N55_N58_N32 | E16: =COUNTIF(Checklist!$B$4:$B$52,$A16) -> 2 | F16: =COUNTIFS(Checklist!$B$4:$B$52,$A16,Checklist!$J$4:$J$52,"<>Yes") -> 0 | G16: =COUNTIFS(Checklist!$B$4:$B$52,$A16,Checklist!$K$4:$K$52,"Pass") -> 0 | H16: =COUNTIFS(Checklist!$B$4:$B$52,$A16,Checklist!$K$4:$K$52,"Fail")+COUNTIFS(Checklist!$B$4:$B$52,$A16,Checklist!$K$4:$K$52,FALSE) -> 0 | I16: =COUNTIFS(Checklist!$B$4:$B$52,$A16,Checklist!$K$4:$K$52,"Blocked") -> 0 | J16: =COUNTIFS(Checklist!$B$4:$B$52,$A16,Checklist!$K$4:$K$52,"N/A") -> 0 | K16: =E16-G16-H16-I16-J16 -> 2 | L16: =F16-COUNTIFS(Checklist!$B$4:$B$52,$A16,Checklist!$J$4:$J$52,"<>Yes",Checklist!$K$4:$K$52,"Pass")-COUNTIFS(Checklist!$B$4:$B$52,$A16,Checklist!$J$4:$J$52,"<>Yes",Checklist!$K$4:$K$52,"N/A") -> 0 | M16: =IF(E16=0,0,(G16+H16+I16+J16)/E16) -> 0 | N16: =IF(H16>0,"Fail",IF(I16>0,"Blocked",IF(L16=0,IF(F16=0,IF(G16+J16=0,"Optional","Pass"),"Pass"),IF(G16+J16=0,"Not started","In progress")))) -> Optional
A18: All | B18: Overall | E18: =SUM(E5:E16) -> 40 | F18: =SUM(F5:F16) -> 29 | G18: =SUM(G5:G16) -> 38 | H18: =SUM(H5:H16) -> 0 | I18: =SUM(I5:I16) -> 0 | J18: =SUM(J5:J16) -> 0 | K18: =SUM(K5:K16) -> 2 | L18: =SUM(L5:L16) -> 0 | M18: =IF(E18=0,0,(G18+H18+I18+J18)/E18) -> 0.95 | N18: =IF(H18>0,"Fail",IF(I18>0,"Blocked",IF(L18=0,"Pass",IF(G18+J18=0,"Not started","In progress")))) -> Pass

Sheet Known issues
A1: What you may see during the checks
A3: Known and expected: don't mark a row Fail for these
A4: You see | B4: ID | C4: Notes
A5: Host quits or stops Play Mode mid-match: the client lands in the Lobby with no Result screen. | B5: N59 | C5: Known; section F measures it. The fix waits for your poll answer (P1).
A6: During 'Waiting for respawn' the HP and Life texts keep their last values (and language) until the respawn. | B6: — | C6: Unchanged behavior: there's no character to read.
A7: Many debug lines in the Editor Console (phases, 'Card clicked', 'DespawnBlock' …). | B7: N34 | C7: Expected in the Editor: the prefabs keep debug on. Only release builds must be quiet (G1.4).
A8: The warning 'Invalid mane material index.' on every pony spawn (also in the release Player.log). | B8: N27 | C8: Parked by you until the mane model exists.
A9: 'No card selected for control package.' when Confirm is pressed with no card picked. | B9: — | C9: Expected warning.
A10: 'Send ignored: no card target was confirmed.' | B10: N20 | C10: Expected: Send needs a confirmed target. No message on screen (feature gap).
A11: 'Only active player can confirm action phase.' when Confirm Turn is pressed during the opponent's Player action. | B11: — | C11: Expected. No message on screen (feature gap).
A12: 'Remote client disconnected. Host continue' when the opponent leaves. | B12: H6 | C12: Expected: the forfeit path.
A13: 'Bootstrap: No saved language code found.' on the very first start. | B13: M12 | C13: Expected until a language is picked once.
A14: The countdown shows 00 for a moment before the phase changes. | B14: N36 | C14: Cosmetic; mark Fail only if it stays for more than about 1 s.
A15: 'Round preparation' still shows while cards are dealt. | B15: — | C15: Feature gap: no draw phase is set.
... A21: MPLUSRounded1c-Medium SDF.asset shows as modified in git status after ru/ja text rendered. | B21: N28 | C21: Expected in the Editor. Restore it before committing (Read me → Before you commit).
A23: Fixed in this round: mark the row Fail if you see these
A24: You see | B24: ID | C24: Checked in
A25: A click on a right-hand (client's) table card opens no big card, in either window. | B25: N54 | C25: A1.2, A2.1
A26: After an early Confirm Turn, the bottom row stays empty for the whole match. | B26: N57 | C26: C1, G1.3
A27: NullReferenceException from ConfirmTargetButtonUI or ConfirmSendButton. | B27: N56 | C27: B2, H1.1
A28: 'Card package rejected. Invalid target count' during normal casting. | B28: N58 | C28: B1, H1.2
A29: Any of the G1.4 debug lines in the release Player.log. | B29: N34 | C29: G1.4
A30: HP or Life text not updating at once, or stuck in the old language while alive. | B30: N35 | C30: D1.1–D1.3
A31: A match that hangs at start with 'No Spawn Point' and nothing spawned. | B31: N55 | C31: E1, I1
A33: Found during the checks (add your own rows here)
A34: What you saw | B34: Row / when | C34: Console text, screenshot
