Workbook

Sheet Read me
A1: Manual two-player checklist: N50/N52, UI6 and UI5 (Issue Reports #10 and #11)
A3: About
A4: Date / baseline | B4: 2026-10-22. HEAD = 72a724c ('Ui5') plus the uncommitted working tree: UI6 (TASK-UI6) and N50/N52 (TASK-N50_N52). Line numbers are from the working tree.
A5: Sources | B5: Issue Report #11 §5 (its C = N50, B = UI6, A = UI5 in a build), Issue Report #10 §5 A, §9 of TASK-N50_N52 and TASK-UI6 (Docs/AI/Tasks/), and Codex's reports 2026-10-22_N50_N52_Implementation.md §6 and 2026-10-22_UI6_Implementation.md.
A6: Code review (Claude) | B6: I compared Codex's N50/N52 change with its start-of-task copies (build/n50-verification/baseline/). It matches the spec: • The preview now finds the HUD canvas and the dock when a preview opens, not in Start, and finds them again after a scene change. • The warning is logged at most once per controller. • N52: a hovered card counts as gone only when the bottom row has no view of it, or when it's destroyed. Codex's Play Mode harness passed every case, including the client order (a controller created under a stand-in Lobby canvas). Its release build succeeded. I didn't run Unity myself. No harness can play a real client, so section A is the real test.
A7: Why | B7: N50 blocks UI6. UI5 hasn't run in a player build yet: your build session on 2026-10-21 ran before UI5 was committed. When this checklist passes, UI6 and N50/N52 can be committed, and N47–N50 and N52 close.
A8: Who runs it | B8: The developer: A and B in two Unity Editors (ParrelSync), C with the Windows player build and the main Editor. The AI agents can't run two instances or judge how things look.
A9: Order | B9: A first: it's the bug you found. Then B: only the Game view size changes. C (the player build) last. There are no temporary code or asset changes this round.
A10: How to report | B10: 1. Set Status on every row of the Checklist sheet. The Summary sheet updates by itself. 2. For every Fail, paste the Console text (error plus stack trace) into 'Console output / notes'. For a visual Fail, save a screenshot and write its file name there. Clear on Play is on, so copy the Console before you press Play again. 3. If you run rows on your second machine, write 'PC 2' in Tested by. 4. Tell Claude when you're done. Claude then updates the report and writes fix specs if needed.
A12: Legend
A13: Cells to fill in | B13: Only the yellow cells: Checklist → Status, Tested by, Date, Console output / notes; Clean-up → Done. Everything else is reference text or formulas.
A14: Pass | B14: Every expected result in the row was seen.
A15: Fail | B15: At least one expected result wasn't seen, or a new error appeared. Add the Console text or a screenshot name.
A16: Blocked | B16: The row couldn't be run (e.g. an earlier failure, the card never drawn). Say why in the notes.
A17: Not run | B17: Skipped on purpose. Fine for optional rows; for a required row it keeps the group open.
A18: N/A | B18: Doesn't apply in this setup. Counts like a Pass for the group result.
A19: Optional = Yes | B19: Optional rows don't hold back a group's Pass result. A8's rows ask for your opinion: write it in the notes.
A20: Grey text | B20: In a group's second and later rows, Check / Covers / Task / Run as / Size repeat the first row so that filtering works. An empty 'Steps' cell means: same steps as the row above.
A22: Example of a filled row
A23: ID / Status | B23: A1.1 → Fail
A24: Tested by / Date | B24: Client window / 2026-10-22
A25: Console output / notes | B25: No big card on hover at 1920×1080. clone-editor.log: <paste the warning or exception here>. Screenshot: A1-1_client.png.
A27: Preparation
A28: 1. The clone with its own log | B28: Close the clone Editor if it's open. Then start it from PowerShell, so that it writes its own log: & 'C:\Program Files\Unity\Hub\Editor\6000.3.13f1\Editor\Unity.exe' -projectPath 'C:\Lesson\FallenStar-Spellcasters_clone_1' -logFile 'C:\Lesson\clone-editor.log' Open the main project as usual. The clone shares Assets, so it runs the same code. Last time both Editors wrote into one Editor.log, and most of the client's lines were lost.
A29: 2. Console | B29: In both Editors, open the Console: Collapse off, Clear on Play on.
A30: 3. Clean start | B30: git status shows no change to Assets/Fonts/MPLUSRounded1c-Medium SDF.asset (Clean-up sheet). Both Editors are in English.
A31: 4. Start a match | B31: Log in and go to the Lobby in both windows. The main Editor presses Create Lobby: from now on it's the host window. The clone presses Find Lobby, selects the lobby and presses Join: it's the client window. The host presses Start game. Section A needs the clone as the client: that's where N50 lived.
A32: 5. Phase log | B32: GameMasterPrefab has m_debugMode = 1, so the host Console logs every phase: 'Round break phase started', 'DrawPhase started', 'Card selection phase started.', 'Player Action phase started', 'Waiting for Respawn', 'GameMaster: match ended …'.
A33: 6. Game view sizes | B33: Game view → the size menu at the top → '+' → add Fixed Resolution presets: 640×480, 800×600, 1024×768, 1280×720, 1280×1024, 1360×768, 1366×768, 1920×1080, 2560×1600, 3440×1440. If the clone doesn't list them, add 1280×720 and 1920×1080 there too. If the Game view is smaller than a preset, Unity scales the picture down; that's fine for layout checks.
A35: Useful facts
A36: The big card | B36: Hovering a card in the bottom row, or left-clicking a card on the board, shows the card large at the left edge, vertically centred. It never takes clicks: they go through it to the board. It hides when the pointer leaves the row or on the next world click.
A37: The bottom row | B37: In Card Selection it shows your hand. In Player action it shows the cards you played this round.
A38: Two layouts | B38: Game view or window narrower than 1366: the compact layout (Leave match bottom-left, smaller hand cards). 1366 or wider: the normal layout (Leave match top-left).
A39: Phases (en) | B39: Line 1 of the announcer: 'Round preparation' (5 s; it still shows while cards are dealt), 'Card Selection' (60 s), 'Player action' (60 s per player), 'Waiting for respawn' (30 s). The number counts down.
A40: Turn order | B40: The player whose selected cards (play and discard) cost more goes first. To go second, select fewer or cheaper cards than the opponent.
A41: Controls | B41: Hand cards: left-click = play, right-click = discard. Confirm Turn confirms the selection in Card Selection, ends your Player action, and confirms the respawn block in Waiting for respawn. Cast in your Player action: left-click a board card → click the target in the world → Confirm → Send. W/A/S/D = one step (own Player action only). Space = −10 HP to yourself (own Player action only; Editor and development builds only).
A42: Cards (en / ru) | B42: Ice Shard / Ледяной осколок: 2 mana, 20 damage to the opponent's pony. Fireball / Огненный шар: 3 mana, 50 damage to an opponent block. Clarity / Ясность: 3 mana, draw 2. Healing Hooves / Исцеляющие копыта: 4 mana, heal yourself 30.
A43: Numbers | B43: Pony HP 100, block HP 100, 3 lives, 25 blocks per player. Mana 2 → 4 → 6 … up to 20. 2 new cards per player per round. Hand limit 10.
A44: Kill a pony at any moment | B44: In the host window's Scene view, select the pony (PonyBase(Clone)) and drag it sideways off its platform, or add about 20 to its Transform Position X or Z. It falls into the lava and dies. Host window only: the lava check runs on the server.
A45: Switch language | B45: Main menu → Settings (remembered). In the lobby or during a match: Window → Asset Management → Localization Scene Controls → Active Locale.
...

Sheet Checklist
A1: Manual two-player checklist: N50/N52, UI6 and UI5 (Issue Reports #10 and #11)
A2: Baseline 72a724c plus the working tree (2026-10-22). Fill in only the yellow columns (Status, Tested by, Date, Console output / notes). 'Size' is the Game view size or the build's window; expected noise is on the Known issues sheet.
A3: ID | B3: Group | C3: Check | D3: Covers | E3: Task | F3: Run as | G3: Size | H3: Steps | I3: Expected result | J3: Optional | K3: Status | L3: Tested by | M3: Date | N3: Console output / notes
A4: A. The big card on both players: two Editors, the clone is the client (N50, N52)
A5: A1.1 | B5: A1 | C5: Client: hovering a hand card shows the big card | D5: N50, N47 | E5: N50_N52 | F5: Client | G5: 1920×1080 | H5: Start a match (Read me → Preparation). Set the clone's Game view to 1920×1080. In Card Selection, in the client window, move the pointer slowly onto each hand card. | I5: As soon as the pointer is on a card, its big card appears at the left edge, vertically centred and fully on screen. (Before the fix, nothing appeared on the client.) | K5: Pass | L5: Owner | M5: 46317
A6: A1.2 | B6: A1 | C6: Client: hovering a hand card shows the big card | D6: N50, N47 | E6: N50_N52 | F6: Client | G6: 1920×1080 | H6: Move straight from one hand card to the next, then off the row. | I6: The big card switches to the card under the pointer, with no flicker and no empty moment. Off the row, it disappears. | K6: Pass | L6: Owner | M6: 46317
A7: A1.3 | B7: A1 | C7: Client: hovering a hand card shows the big card | D7: N50, N47 | E7: N50_N52 | F7: Client | G7: 1920×1080 | H7: Hover a card and left-click it (play). Hover another one and right-click it (discard). Click both again to deselect. | I7: The big card stays visible while you click. The play and discard highlights work as before. | K7: Pass | L7: Owner | M7: 46317
A8: A2.1 | B8: A2 | C8: Client: clicking a board card shows the big card; targeting still works | D8: N50, N47 | E8: N50_N52 | F8: Client | G8: 1920×1080 | H8: Select 1–2 cards to play and press Confirm Turn. In the client's own Player action, left-click each of your board cards (your played cards lying on the table). | I8: Each click shows that card as the big card at the left. | K8: FALSE | L8: Owner | M8: 46317
A9: A2.2 | B9: A2 | C9: Client: clicking a board card shows the big card; targeting still works | D9: N50, N47 | E9: N50_N52 | F9: Client | G9: 1920×1080 | H9: Left-click the opponent's board cards (the host must have played some this round). | I9: The big card shows the opponent's card too. | K9: Pass | L9: Owner | M9: 46317
A10: A2.3 | B10: A2 | C10: Client: clicking a board card shows the big card; targeting still works | D10: N50, N47 | E10: N50_N52 | F10: Client | G10: 1920×1080 | H10: Cast a card: click your board card → click its target (the opponent's pony for Ice Shard, an opponent block for Fireball) → Confirm → Send. If the target sits behind the big card at the left, click it there. | I10: The target click reaches the target even through the big card, and the cast resolves. | K10: Pass | L10: Owner | M10: 46317
A11: A2.4 | B11: A2 | C11: Client: clicking a board card shows the big card; targeting still works | D11: N50, N47 | E11: N50_N52 | F11: Client | G11: 1920×1080 | H11: With a big card shown, left-click empty ground or the sky. | I11: The big card disappears. | K11: Pass | L11: Owner | M11: 46317
A12: A3.1 | B12: A3 | C12: A played card's big card stays while hovered and goes when the card leaves the row | D12: N52 | E12: N50_N52 | F12: Client | G12: 1920×1080 | H12: In the client's own Player action, with at least one played card in the bottom row, rest the pointer on a played card in that row. Don't move it for about 5 s. | I12: Its big card stays shown the whole time. | K12: Pass | L12: Owner | M12: 46317 | N12: Work if point card in bottom HUD, don’t work if point and click on board card
A13: A3.2 | B13: A3 | C13: A played card's big card stays while hovered and goes when the card leaves the row | D13: N52 | E13: N50_N52 | F13: Client | G13: 1920×1080 | H13: Keep the pointer still on an unused played card in the bottom row until your Player action ends (the countdown reaches 0, about 60 s). | I13: When your Player action ends, the row empties and the big card disappears with it. It doesn't stay on screen. | K13: Pass | L13: Owner | M13: 46317
A14: A4.1 | B14: A4 | C14: Client: the big card at a low size | D14: N50, UI6 | E14: N50_N52 | F14: Client | G14: 1280×720 | H14: Set the clone's Game view to 1280×720 (the low layout). Repeat A1.1 and A2.1 on the client. | I14: The compact HUD. The big card appears at the left, smaller than at 1920×1080, fully on screen. | K14: Pass | L14: Owner | M14: 46317
A15: A4.2 | B15: A4 | C15: Client: the big card at a low size | D15: N50, UI6 | E15: N50_N52 | F15: Client | G15: 1280×720 | H15: With a big card shown, switch the clone's Game view between 1280×720 and 1920×1080. | I15: If the big card is still shown, it resizes at once to fit. If the click on the size menu hid it (Known issues), hover a card again: it shows at the new size. | J15: Yes | K15: Pass | L15: Owner | M15: 46317
A16: A5.1 | B16: A5 | C16: Host: nothing changed | D16: N50 (host side) | E16: N50_N52 | F16: Host | G16: 1920×1080 | H16: In the host window (main Editor, Game view 1920×1080), repeat A1.1–A1.3 and A2.1–A2.4. | I16: The same results as on the client. The big card has the same size and place as on the client at the same Game view size. | K16: Pass | L16: Owner | M16: 46317 | N16: Same issue. We can preview clients card on map. Host's card OK.
A17: A6.1 | B17: A6 | C17: A second match without restarting the Editors | D17: N50 | E17: N50_N52 | F17: Both | G17: any | H17: Finish the match (or the client presses Leave match → Leave). From the Result screen go back, then create, join and start a new match with the same two Editors. Don't stop Play Mode or restart either Editor. | I17: In the second match, hovering (A1.1) and board clicks (A2.1) show the big card on the client. | K17: Pass | L17: Owner | M17: 46317
A18: A6.2 | B18: A6 | C18: A second match without restarting the Editors | D18: N50 | E18: N50_N52 | F18: Both | G18: any | I18: The same on the host. | K18: Pass | L18: Owner | M18: 46317
A19: A7.1 | B19: A7 | C19: Both Editor logs are clean | D19: N50, N34 | E19: N50_N52 | F19: Both | G19: — | H19: After A1–A6, search the main Editor's Console and C:\Lesson\clone-editor.log for 'no screen-space canvas' and 'Exception'. | I19: No 'CardPreviewController: no screen-space canvas found; previews are disabled.' in either. No exception from game code (the expected ones are on the Known issues sheet). | K19: Pass | L19: Owner | M19: 46317
A20: A8.1 | B20: A8 | C20: Your notes: does the big card get in the way? | D20: U15, U16 | E20: UI6 | F20: Both | G20: any | H20: During A1–A6, in both windows: did the big card ever cover something you needed? For example the left side of the board, the banner's left end, or the leftmost hand cards at 1280×720. | I20: Write your answer in the notes. Pass = it never got in the way. Fail = it did; say where. (U15. The fallback is V2b: the big card at the mouse.) | J20: Yes | K20: Pass | L20: Owner | M20: 46317 | N20: it never got in the way, all visible
A21: A8.2 | B21: A8 | C21: Your notes: does the big card get in the way? | D21: U15, U16 | E21: UI6 | F21: Both | G21: any | H21: In Card Selection: did the hover big card distract you (flicker, covering, appearing too eagerly)? | I21: Write your answer in the notes. Pass = fine. Fail = distracting. (U16. The fallbacks are V2c, board cards only, or a hover delay of about 0.3 s.) | J21: Yes | K21: Pass | L21: Owner | M21: 46317 | N21: Fine, in future possible add disapering/show on animation
A22: B. The UI6 HUD at several Game view sizes: two Editors
A23: B1.1 | B23: B1 | C23: 2560×1600: the HUD as before, plus the new button column | D23: UI6, N48 | E23: UI6 | F23: Either | G23: 2560×1600 | H23: Main Editor's Game view 2560×1600, during a match. Compare the HUD with the last checklist or your memory. | I23: HP, Life and mana top-right; Leave match top-left; the banner top-centre; the hand bottom-centre: as before. Changed on purpose: Confirm, Send and Confirm Turn form one column bottom-right, all with the wide wooden plank, and the labels are slightly larger. | K23: Pass | L23: Owner | M23: 46317
A24: B1.2 | B24: B1 | C24: 2560×1600: the HUD as before, plus the new button column | D24: UI6, N48 | E24: UI6 | F24: Either | G24: 2560×1600 | H24: In your own Player action, select a board card and a target so that Confirm and Send show. Look in en, ru and ja (Localization Scene Controls). | I24: Top to bottom: Confirm, Send, Confirm Turn, not overlapping. Every label fits inside its button: 'Подтвердить', 'Отправить', 'Подтвердить ход' in ru; '確認', '送信', 'ターンを確認' in ja. | K24: Pass | L24: Owner | M24: 46317
A25: B2.1 | B25: B2 | C25: Low sizes: the compact layout, readable in en, ru and ja | D25: UI6, N47, N48 | E25: UI6 | F25: Either | G25: 640×480 … 1360×768 | H25: Game view 1280×720, during a match. | I25: The compact layout: the banner top-centre, HP/Life/mana top-right, Leave match bottom-left, the hand bottom-centre with smaller cards, the button column bottom-right. Nothing cut, nothing overlapping. | K25: Pass | L25: Owner | M25: 46317
A26: B2.2 | B26: B2 | C26: Low sizes: the compact layout, readable in en, ru and ja | D26: UI6, N47, N48 | E26: UI6 | F26: Either | G26: 640×480 … 1360×768 | H26: The same at 640×480, 800×600, 1024×768, 1280×1024 and 1360×768. | I26: Same as B2.1 at every size. | K26: Pass | L26: Owner | M26: 46317
A27: B2.3 | B27: B2 | C27: Low sizes: the compact layout, readable in en, ru and ja | D27: UI6, N47, N48 | E27: UI6 | F27: Either | G27: 640×480 … 1360×768 | H27: At 1024×768, switch en → ru → ja. In each language read the announcer, HP/Life/mana, Leave match and the three buttons (select a board card and a target to show Confirm and Send). | I27: All text is readable in all three languages, and every label fits inside its button. | K27: Pass | L27: Owner | M27: 46317
A28: B2.4 | B28: B2 | C28: Low sizes: the compact layout, readable in en, ru and ja | D28: UI6, N47, N48 | E28: UI6 | F28: Either | G28: 640×480 … 1360×768 | H28: At 1024×768, hover a hand card in Card Selection, and click a board card in Player action. Read the big card. | I28: The card name and description are readable. This is last round's failed B4.3 ('Cant read buttons/cards text': N47, N48). Long Russian descriptions are smaller (B6, N51). | K28: Pass | L28: Owner | M28: 46317
A29: B2.5 | B29: B2 | C29: Low sizes: the compact layout, readable in en, ru and ja | D29: UI6, N47, N48 | E29: UI6 | F29: Either | G29: 640×480 … 1360×768 | H29: At 640×480, press Leave match, then Cancel. | I29: The dark panel covers the view, and the dialog with both buttons fits on screen. Cancel closes it. | K29: Pass | L29: Owner | M29: 46317
A30: B3.1 | B30: B3 | C30: The layout switch at 1366 wide | D30: UI6 | E30: UI6 | F30: Either | G30: 1360×768 ↔ 1366×768 | H30: During a match with 5 or more hand cards, switch the Game view 1360×768 → 1366×768 → 1360×768. | I30: The layout switches at once each time (compact ↔ normal). The hand re-centres and re-spaces. No error in the Console. | K30: Pass | L30: Owner | M30: 46317
A31: B4.1 | B31: B4 | C31: Medium and high sizes | D31: UI6, N48, N53 | E31: UI6 | F31: Either | G31: 1366×768, 1920×1080, 3440×1440 | H31: Game view 1366×768, then 1920×1080, then 3440×1440, during a match, in en and in ru. | I31: All text is readable, and nothing is cut. The mana texts don't touch the banner (their boxes do: N53, Known issues). | K31: Pass | L31: Owner | M31: 46317
A32: B4.2 | B32: B4 | C32: Medium and high sizes | D32: UI6, N48, N53 | E32: UI6 | F32: Either | G32: 1366×768, 1920×1080, 3440×1440 | H32: At each of the three sizes, hover a hand card and click a board card. | I32: The big card shows at the left, above the hand and below Leave match, fully on screen. | K32: Pass | L32: Owner | M32: 46317
A33: B5.1 | B33: B5 | C33: The client's HUD matches the host's | D33: UI6 | E33: UI6 | F33: Both | G33: 1920×1080, 1280×720 | H33: Set both Game views to 1920×1080, then both to 1280×720. Compare the two windows during a match. | I33: At each size the client's HUD looks like the host's: the same layout, label sizes and big card size. | K33: Pass | L33: Owner | M33: 46317
A34: B6.1 | B34: B6 | C34: Long Russian descriptions in the big card (your decision W1) | D34: N51 | E34: UI6 | F34: Either | G34: 1366×768 | H34: Game view 1366×768, Russian. Show the big card of 'Исцеляющие копыта' (Healing Hooves, 4 mana; from round 2), and of 'Огненный шар' and 'Ледяной осколок' if you have them. | I34: Write in the notes whether the descriptions are comfortable to read. Pass = fine. Fail = too small. (Known: N51. Your answer settles decision W1.) | K34: Pass | L34: Owner | M34: 46317 | N34: Fine
A35: C. Player build: Settings (UI5), the windowed size (N49) and the big card in a build
A36: C1.1 | B36: C1 | C36: Release player build | D36: — | E36: UI5 + UI6 | F36: Build | G36: — | H36: With both Editors out of Play Mode: File → Build Profiles → Windows, Development Build off. Build to C:\Lesson\Spellcasters.Build\ (replace the old build). | I36: The build succeeds with no errors. | K36: Pass | L36: Owner | M36: 46317
A37: C2.1 | B37: C2 | C37: Windowed: the largest size above the taskbar, then 1366×768 | D37: UI5, N49 | E37: UI5 + UI6 | F37: Build | G37: window | H37: Start C:\Lesson\Spellcasters.Build\FallenStar-Spellcasters.exe. Main menu → Settings → Display mode → Windowed. | I37: A window with a title bar. On your 2560×1600 display it's 1920 × 1200, and the whole window, title bar and bottom edge, is above the taskbar. Resolution shows 1920 × 1200. (On PC 2: the largest size of the display's shape that fits above its taskbar.) | K37: Pass | L37: Owner | M37: 46317
A38: C2.2 | B38: C2 | C38: Windowed: the largest size above the taskbar, then 1366×768 | D38: UI5, N49 | E38: UI5 + UI6 | F38: Build | G38: window | H38: Open the Resolution list and pick the largest size. | I38: The whole window, title bar included, is still on screen and above the taskbar. | K38: Pass | L38: Owner | M38: 46317
A39: C2.3 | B39: C2 | C39: Windowed: the largest size above the taskbar, then 1366×768 | D39: UI5, N49 | E39: UI5 + UI6 | F39: Build | G39: window | H39: Resolution → 1366 × 768. | I39: The window shrinks to 1366×768. Nothing on the Settings screen is cut. | K39: Pass | L39: Owner | M39: 46317
A40: C3.1 | B40: C3 | C40: Fullscreen: native size, then 1920×1080 with bars | D40: UI5 | E40: UI5 | F40: Build | G40: fullscreen | H40: Display mode → Fullscreen. | I40: The game fills the display at its native size (2560 × 1600 on your display), and Resolution shows that size. | K40: Pass | L40: Owner | M40: 46317
...

Sheet Summary
A1: Results summary
A2: Calculated from the Checklist sheet; don't edit. Result: Fail if any row failed, Blocked if any row is blocked, Pass when every required row is Pass or N/A, Optional when a group has only optional rows and none is filled in.
A4: Group | B4: Check | C4: Covers | D4: Task | E4: Items | F4: Required | G4: Pass | H4: Fail | I4: Blocked | J4: N/A | K4: Not run / empty | L4: Open (required) | M4: Done % | N4: Result
A5: A1 | B5: Client: hovering a hand card shows the big card | C5: N50, N47 | D5: N50_N52 | E5: =COUNTIF(Checklist!$B$4:$B$50,$A5) -> 3 | F5: =COUNTIFS(Checklist!$B$4:$B$50,$A5,Checklist!$J$4:$J$50,"<>Yes") -> 3 | G5: =COUNTIFS(Checklist!$B$4:$B$50,$A5,Checklist!$K$4:$K$50,"Pass") -> 3 | H5: =COUNTIFS(Checklist!$B$4:$B$50,$A5,Checklist!$K$4:$K$50,"Fail") -> 0 | I5: =COUNTIFS(Checklist!$B$4:$B$50,$A5,Checklist!$K$4:$K$50,"Blocked") -> 0 | J5: =COUNTIFS(Checklist!$B$4:$B$50,$A5,Checklist!$K$4:$K$50,"N/A") -> 0 | K5: =E5-G5-H5-I5-J5 -> 0 | L5: =COUNTIFS(Checklist!$B$4:$B$50,$A5,Checklist!$J$4:$J$50,"<>Yes",Checklist!$K$4:$K$50,"<>Pass",Checklist!$K$4:$K$50,"<>N/A") -> 0 | M5: =IF(E5=0,0,(G5+H5+I5+J5)/E5) -> 1 | N5: =IF(H5>0,"Fail",IF(I5>0,"Blocked",IF(G5+H5+I5+J5=0,IF(F5=0,"Optional","Not started"),IF(L5=0,"Pass","In progress")))) -> Pass
A6: A2 | B6: Client: clicking a board card shows the big card; targeting still works | C6: N50, N47 | D6: N50_N52 | E6: =COUNTIF(Checklist!$B$4:$B$50,$A6) -> 4 | F6: =COUNTIFS(Checklist!$B$4:$B$50,$A6,Checklist!$J$4:$J$50,"<>Yes") -> 4 | G6: =COUNTIFS(Checklist!$B$4:$B$50,$A6,Checklist!$K$4:$K$50,"Pass") -> 3 | H6: =COUNTIFS(Checklist!$B$4:$B$50,$A6,Checklist!$K$4:$K$50,"Fail") -> 0 | I6: =COUNTIFS(Checklist!$B$4:$B$50,$A6,Checklist!$K$4:$K$50,"Blocked") -> 0 | J6: =COUNTIFS(Checklist!$B$4:$B$50,$A6,Checklist!$K$4:$K$50,"N/A") -> 0 | K6: =E6-G6-H6-I6-J6 -> 1 | L6: =COUNTIFS(Checklist!$B$4:$B$50,$A6,Checklist!$J$4:$J$50,"<>Yes",Checklist!$K$4:$K$50,"<>Pass",Checklist!$K$4:$K$50,"<>N/A") -> 1 | M6: =IF(E6=0,0,(G6+H6+I6+J6)/E6) -> 0.75 | N6: =IF(H6>0,"Fail",IF(I6>0,"Blocked",IF(G6+H6+I6+J6=0,IF(F6=0,"Optional","Not started"),IF(L6=0,"Pass","In progress")))) -> In progress
A7: A3 | B7: A played card's big card stays while hovered and goes when the card leaves the row | C7: N52 | D7: N50_N52 | E7: =COUNTIF(Checklist!$B$4:$B$50,$A7) -> 2 | F7: =COUNTIFS(Checklist!$B$4:$B$50,$A7,Checklist!$J$4:$J$50,"<>Yes") -> 2 | G7: =COUNTIFS(Checklist!$B$4:$B$50,$A7,Checklist!$K$4:$K$50,"Pass") -> 2 | H7: =COUNTIFS(Checklist!$B$4:$B$50,$A7,Checklist!$K$4:$K$50,"Fail") -> 0 | I7: =COUNTIFS(Checklist!$B$4:$B$50,$A7,Checklist!$K$4:$K$50,"Blocked") -> 0 | J7: =COUNTIFS(Checklist!$B$4:$B$50,$A7,Checklist!$K$4:$K$50,"N/A") -> 0 | K7: =E7-G7-H7-I7-J7 -> 0 | L7: =COUNTIFS(Checklist!$B$4:$B$50,$A7,Checklist!$J$4:$J$50,"<>Yes",Checklist!$K$4:$K$50,"<>Pass",Checklist!$K$4:$K$50,"<>N/A") -> 0 | M7: =IF(E7=0,0,(G7+H7+I7+J7)/E7) -> 1 | N7: =IF(H7>0,"Fail",IF(I7>0,"Blocked",IF(G7+H7+I7+J7=0,IF(F7=0,"Optional","Not started"),IF(L7=0,"Pass","In progress")))) -> Pass
A8: A4 | B8: Client: the big card at a low size | C8: N50, UI6 | D8: N50_N52 | E8: =COUNTIF(Checklist!$B$4:$B$50,$A8) -> 2 | F8: =COUNTIFS(Checklist!$B$4:$B$50,$A8,Checklist!$J$4:$J$50,"<>Yes") -> 1 | G8: =COUNTIFS(Checklist!$B$4:$B$50,$A8,Checklist!$K$4:$K$50,"Pass") -> 2 | H8: =COUNTIFS(Checklist!$B$4:$B$50,$A8,Checklist!$K$4:$K$50,"Fail") -> 0 | I8: =COUNTIFS(Checklist!$B$4:$B$50,$A8,Checklist!$K$4:$K$50,"Blocked") -> 0 | J8: =COUNTIFS(Checklist!$B$4:$B$50,$A8,Checklist!$K$4:$K$50,"N/A") -> 0 | K8: =E8-G8-H8-I8-J8 -> 0 | L8: =COUNTIFS(Checklist!$B$4:$B$50,$A8,Checklist!$J$4:$J$50,"<>Yes",Checklist!$K$4:$K$50,"<>Pass",Checklist!$K$4:$K$50,"<>N/A") -> 0 | M8: =IF(E8=0,0,(G8+H8+I8+J8)/E8) -> 1 | N8: =IF(H8>0,"Fail",IF(I8>0,"Blocked",IF(G8+H8+I8+J8=0,IF(F8=0,"Optional","Not started"),IF(L8=0,"Pass","In progress")))) -> Pass
A9: A5 | B9: Host: nothing changed | C9: N50 (host side) | D9: N50_N52 | E9: =COUNTIF(Checklist!$B$4:$B$50,$A9) -> 1 | F9: =COUNTIFS(Checklist!$B$4:$B$50,$A9,Checklist!$J$4:$J$50,"<>Yes") -> 1 | G9: =COUNTIFS(Checklist!$B$4:$B$50,$A9,Checklist!$K$4:$K$50,"Pass") -> 1 | H9: =COUNTIFS(Checklist!$B$4:$B$50,$A9,Checklist!$K$4:$K$50,"Fail") -> 0 | I9: =COUNTIFS(Checklist!$B$4:$B$50,$A9,Checklist!$K$4:$K$50,"Blocked") -> 0 | J9: =COUNTIFS(Checklist!$B$4:$B$50,$A9,Checklist!$K$4:$K$50,"N/A") -> 0 | K9: =E9-G9-H9-I9-J9 -> 0 | L9: =COUNTIFS(Checklist!$B$4:$B$50,$A9,Checklist!$J$4:$J$50,"<>Yes",Checklist!$K$4:$K$50,"<>Pass",Checklist!$K$4:$K$50,"<>N/A") -> 0 | M9: =IF(E9=0,0,(G9+H9+I9+J9)/E9) -> 1 | N9: =IF(H9>0,"Fail",IF(I9>0,"Blocked",IF(G9+H9+I9+J9=0,IF(F9=0,"Optional","Not started"),IF(L9=0,"Pass","In progress")))) -> Pass
A10: A6 | B10: A second match without restarting the Editors | C10: N50 | D10: N50_N52 | E10: =COUNTIF(Checklist!$B$4:$B$50,$A10) -> 2 | F10: =COUNTIFS(Checklist!$B$4:$B$50,$A10,Checklist!$J$4:$J$50,"<>Yes") -> 2 | G10: =COUNTIFS(Checklist!$B$4:$B$50,$A10,Checklist!$K$4:$K$50,"Pass") -> 2 | H10: =COUNTIFS(Checklist!$B$4:$B$50,$A10,Checklist!$K$4:$K$50,"Fail") -> 0 | I10: =COUNTIFS(Checklist!$B$4:$B$50,$A10,Checklist!$K$4:$K$50,"Blocked") -> 0 | J10: =COUNTIFS(Checklist!$B$4:$B$50,$A10,Checklist!$K$4:$K$50,"N/A") -> 0 | K10: =E10-G10-H10-I10-J10 -> 0 | L10: =COUNTIFS(Checklist!$B$4:$B$50,$A10,Checklist!$J$4:$J$50,"<>Yes",Checklist!$K$4:$K$50,"<>Pass",Checklist!$K$4:$K$50,"<>N/A") -> 0 | M10: =IF(E10=0,0,(G10+H10+I10+J10)/E10) -> 1 | N10: =IF(H10>0,"Fail",IF(I10>0,"Blocked",IF(G10+H10+I10+J10=0,IF(F10=0,"Optional","Not started"),IF(L10=0,"Pass","In progress")))) -> Pass
A11: A7 | B11: Both Editor logs are clean | C11: N50, N34 | D11: N50_N52 | E11: =COUNTIF(Checklist!$B$4:$B$50,$A11) -> 1 | F11: =COUNTIFS(Checklist!$B$4:$B$50,$A11,Checklist!$J$4:$J$50,"<>Yes") -> 1 | G11: =COUNTIFS(Checklist!$B$4:$B$50,$A11,Checklist!$K$4:$K$50,"Pass") -> 1 | H11: =COUNTIFS(Checklist!$B$4:$B$50,$A11,Checklist!$K$4:$K$50,"Fail") -> 0 | I11: =COUNTIFS(Checklist!$B$4:$B$50,$A11,Checklist!$K$4:$K$50,"Blocked") -> 0 | J11: =COUNTIFS(Checklist!$B$4:$B$50,$A11,Checklist!$K$4:$K$50,"N/A") -> 0 | K11: =E11-G11-H11-I11-J11 -> 0 | L11: =COUNTIFS(Checklist!$B$4:$B$50,$A11,Checklist!$J$4:$J$50,"<>Yes",Checklist!$K$4:$K$50,"<>Pass",Checklist!$K$4:$K$50,"<>N/A") -> 0 | M11: =IF(E11=0,0,(G11+H11+I11+J11)/E11) -> 1 | N11: =IF(H11>0,"Fail",IF(I11>0,"Blocked",IF(G11+H11+I11+J11=0,IF(F11=0,"Optional","Not started"),IF(L11=0,"Pass","In progress")))) -> Pass
A12: A8 | B12: Your notes: does the big card get in the way? | C12: U15, U16 | D12: UI6 | E12: =COUNTIF(Checklist!$B$4:$B$50,$A12) -> 2 | F12: =COUNTIFS(Checklist!$B$4:$B$50,$A12,Checklist!$J$4:$J$50,"<>Yes") -> 0 | G12: =COUNTIFS(Checklist!$B$4:$B$50,$A12,Checklist!$K$4:$K$50,"Pass") -> 2 | H12: =COUNTIFS(Checklist!$B$4:$B$50,$A12,Checklist!$K$4:$K$50,"Fail") -> 0 | I12: =COUNTIFS(Checklist!$B$4:$B$50,$A12,Checklist!$K$4:$K$50,"Blocked") -> 0 | J12: =COUNTIFS(Checklist!$B$4:$B$50,$A12,Checklist!$K$4:$K$50,"N/A") -> 0 | K12: =E12-G12-H12-I12-J12 -> 0 | L12: =COUNTIFS(Checklist!$B$4:$B$50,$A12,Checklist!$J$4:$J$50,"<>Yes",Checklist!$K$4:$K$50,"<>Pass",Checklist!$K$4:$K$50,"<>N/A") -> 0 | M12: =IF(E12=0,0,(G12+H12+I12+J12)/E12) -> 1 | N12: =IF(H12>0,"Fail",IF(I12>0,"Blocked",IF(G12+H12+I12+J12=0,IF(F12=0,"Optional","Not started"),IF(L12=0,"Pass","In progress")))) -> Pass
A13: B1 | B13: 2560×1600: the HUD as before, plus the new button column | C13: UI6, N48 | D13: UI6 | E13: =COUNTIF(Checklist!$B$4:$B$50,$A13) -> 2 | F13: =COUNTIFS(Checklist!$B$4:$B$50,$A13,Checklist!$J$4:$J$50,"<>Yes") -> 2 | G13: =COUNTIFS(Checklist!$B$4:$B$50,$A13,Checklist!$K$4:$K$50,"Pass") -> 2 | H13: =COUNTIFS(Checklist!$B$4:$B$50,$A13,Checklist!$K$4:$K$50,"Fail") -> 0 | I13: =COUNTIFS(Checklist!$B$4:$B$50,$A13,Checklist!$K$4:$K$50,"Blocked") -> 0 | J13: =COUNTIFS(Checklist!$B$4:$B$50,$A13,Checklist!$K$4:$K$50,"N/A") -> 0 | K13: =E13-G13-H13-I13-J13 -> 0 | L13: =COUNTIFS(Checklist!$B$4:$B$50,$A13,Checklist!$J$4:$J$50,"<>Yes",Checklist!$K$4:$K$50,"<>Pass",Checklist!$K$4:$K$50,"<>N/A") -> 0 | M13: =IF(E13=0,0,(G13+H13+I13+J13)/E13) -> 1 | N13: =IF(H13>0,"Fail",IF(I13>0,"Blocked",IF(G13+H13+I13+J13=0,IF(F13=0,"Optional","Not started"),IF(L13=0,"Pass","In progress")))) -> Pass
A14: B2 | B14: Low sizes: the compact layout, readable in en, ru and ja | C14: UI6, N47, N48 | D14: UI6 | E14: =COUNTIF(Checklist!$B$4:$B$50,$A14) -> 5 | F14: =COUNTIFS(Checklist!$B$4:$B$50,$A14,Checklist!$J$4:$J$50,"<>Yes") -> 5 | G14: =COUNTIFS(Checklist!$B$4:$B$50,$A14,Checklist!$K$4:$K$50,"Pass") -> 5 | H14: =COUNTIFS(Checklist!$B$4:$B$50,$A14,Checklist!$K$4:$K$50,"Fail") -> 0 | I14: =COUNTIFS(Checklist!$B$4:$B$50,$A14,Checklist!$K$4:$K$50,"Blocked") -> 0 | J14: =COUNTIFS(Checklist!$B$4:$B$50,$A14,Checklist!$K$4:$K$50,"N/A") -> 0 | K14: =E14-G14-H14-I14-J14 -> 0 | L14: =COUNTIFS(Checklist!$B$4:$B$50,$A14,Checklist!$J$4:$J$50,"<>Yes",Checklist!$K$4:$K$50,"<>Pass",Checklist!$K$4:$K$50,"<>N/A") -> 0 | M14: =IF(E14=0,0,(G14+H14+I14+J14)/E14) -> 1 | N14: =IF(H14>0,"Fail",IF(I14>0,"Blocked",IF(G14+H14+I14+J14=0,IF(F14=0,"Optional","Not started"),IF(L14=0,"Pass","In progress")))) -> Pass
A15: B3 | B15: The layout switch at 1366 wide | C15: UI6 | D15: UI6 | E15: =COUNTIF(Checklist!$B$4:$B$50,$A15) -> 1 | F15: =COUNTIFS(Checklist!$B$4:$B$50,$A15,Checklist!$J$4:$J$50,"<>Yes") -> 1 | G15: =COUNTIFS(Checklist!$B$4:$B$50,$A15,Checklist!$K$4:$K$50,"Pass") -> 1 | H15: =COUNTIFS(Checklist!$B$4:$B$50,$A15,Checklist!$K$4:$K$50,"Fail") -> 0 | I15: =COUNTIFS(Checklist!$B$4:$B$50,$A15,Checklist!$K$4:$K$50,"Blocked") -> 0 | J15: =COUNTIFS(Checklist!$B$4:$B$50,$A15,Checklist!$K$4:$K$50,"N/A") -> 0 | K15: =E15-G15-H15-I15-J15 -> 0 | L15: =COUNTIFS(Checklist!$B$4:$B$50,$A15,Checklist!$J$4:$J$50,"<>Yes",Checklist!$K$4:$K$50,"<>Pass",Checklist!$K$4:$K$50,"<>N/A") -> 0 | M15: =IF(E15=0,0,(G15+H15+I15+J15)/E15) -> 1 | N15: =IF(H15>0,"Fail",IF(I15>0,"Blocked",IF(G15+H15+I15+J15=0,IF(F15=0,"Optional","Not started"),IF(L15=0,"Pass","In progress")))) -> Pass
A16: B4 | B16: Medium and high sizes | C16: UI6, N48, N53 | D16: UI6 | E16: =COUNTIF(Checklist!$B$4:$B$50,$A16) -> 2 | F16: =COUNTIFS(Checklist!$B$4:$B$50,$A16,Checklist!$J$4:$J$50,"<>Yes") -> 2 | G16: =COUNTIFS(Checklist!$B$4:$B$50,$A16,Checklist!$K$4:$K$50,"Pass") -> 2 | H16: =COUNTIFS(Checklist!$B$4:$B$50,$A16,Checklist!$K$4:$K$50,"Fail") -> 0 | I16: =COUNTIFS(Checklist!$B$4:$B$50,$A16,Checklist!$K$4:$K$50,"Blocked") -> 0 | J16: =COUNTIFS(Checklist!$B$4:$B$50,$A16,Checklist!$K$4:$K$50,"N/A") -> 0 | K16: =E16-G16-H16-I16-J16 -> 0 | L16: =COUNTIFS(Checklist!$B$4:$B$50,$A16,Checklist!$J$4:$J$50,"<>Yes",Checklist!$K$4:$K$50,"<>Pass",Checklist!$K$4:$K$50,"<>N/A") -> 0 | M16: =IF(E16=0,0,(G16+H16+I16+J16)/E16) -> 1 | N16: =IF(H16>0,"Fail",IF(I16>0,"Blocked",IF(G16+H16+I16+J16=0,IF(F16=0,"Optional","Not started"),IF(L16=0,"Pass","In progress")))) -> Pass
... A27: C9 | B27: Player.log is clean | C27: N50, N34 | D27: UI5 + UI6 | E27: =COUNTIF(Checklist!$B$4:$B$50,$A27) -> 1 | F27: =COUNTIFS(Checklist!$B$4:$B$50,$A27,Checklist!$J$4:$J$50,"<>Yes") -> 1 | G27: =COUNTIFS(Checklist!$B$4:$B$50,$A27,Checklist!$K$4:$K$50,"Pass") -> 1 | H27: =COUNTIFS(Checklist!$B$4:$B$50,$A27,Checklist!$K$4:$K$50,"Fail") -> 0 | I27: =COUNTIFS(Checklist!$B$4:$B$50,$A27,Checklist!$K$4:$K$50,"Blocked") -> 0 | J27: =COUNTIFS(Checklist!$B$4:$B$50,$A27,Checklist!$K$4:$K$50,"N/A") -> 0 | K27: =E27-G27-H27-I27-J27 -> 0 | L27: =COUNTIFS(Checklist!$B$4:$B$50,$A27,Checklist!$J$4:$J$50,"<>Yes",Checklist!$K$4:$K$50,"<>Pass",Checklist!$K$4:$K$50,"<>N/A") -> 0 | M27: =IF(E27=0,0,(G27+H27+I27+J27)/E27) -> 1 | N27: =IF(H27>0,"Fail",IF(I27>0,"Blocked",IF(G27+H27+I27+J27=0,IF(F27=0,"Optional","Not started"),IF(L27=0,"Pass","In progress")))) -> Pass
A28: Total | B28: All checks | E28: =SUM(E5:E27) -> 44 | F28: =SUM(F5:F27) -> 41 | G28: =SUM(G5:G27) -> 43 | H28: =SUM(H5:H27) -> 0 | I28: =SUM(I5:I27) -> 0 | J28: =SUM(J5:J27) -> 0 | K28: =SUM(K5:K27) -> 1 | L28: =SUM(L5:L27) -> 1 | M28: =IF(E28=0,0,(G28+H28+I28+J28)/E28) -> 0.97727273 | N28: =IF(H28>0,"Fail",IF(I28>0,"Blocked",IF(G28+H28+I28+J28=0,IF(F28=0,"Optional","Not started"),IF(L28=0,"Pass","In progress")))) -> In progress
A30: By task
A31: Task | B31: What it covers | E31: Items | F31: Required | G31: Pass | H31: Fail | I31: Blocked | J31: N/A | K31: Not run / empty | L31: Open (required) | M31: Done % | N31: Result
A32: N50_N52 | B32: The big card on a client (N50) and the played-card hover (N52) | E32: =COUNTIF(Checklist!$E$4:$E$50,$A32) -> 15 | F32: =COUNTIFS(Checklist!$E$4:$E$50,$A32,Checklist!$J$4:$J$50,"<>Yes") -> 14 | G32: =COUNTIFS(Checklist!$E$4:$E$50,$A32,Checklist!$K$4:$K$50,"Pass") -> 14 | H32: =COUNTIFS(Checklist!$E$4:$E$50,$A32,Checklist!$K$4:$K$50,"Fail") -> 0 | I32: =COUNTIFS(Checklist!$E$4:$E$50,$A32,Checklist!$K$4:$K$50,"Blocked") -> 0 | J32: =COUNTIFS(Checklist!$E$4:$E$50,$A32,Checklist!$K$4:$K$50,"N/A") -> 0 | K32: =E32-G32-H32-I32-J32 -> 1 | L32: =COUNTIFS(Checklist!$E$4:$E$50,$A32,Checklist!$J$4:$J$50,"<>Yes",Checklist!$K$4:$K$50,"<>Pass",Checklist!$K$4:$K$50,"<>N/A") -> 1 | M32: =IF(E32=0,0,(G32+H32+I32+J32)/E32) -> 0.93333333 | N32: =IF(H32>0,"Fail",IF(I32>0,"Blocked",IF(G32+H32+I32+J32=0,IF(F32=0,"Optional","Not started"),IF(L32=0,"Pass","In progress")))) -> In progress
A33: UI6 | B33: Readability profiles: the HUD layouts, labels, big card (N47, N48), U15/U16, N51 | E33: =COUNTIF(Checklist!$E$4:$E$50,$A33) -> 14 | F33: =COUNTIFS(Checklist!$E$4:$E$50,$A33,Checklist!$J$4:$J$50,"<>Yes") -> 12 | G33: =COUNTIFS(Checklist!$E$4:$E$50,$A33,Checklist!$K$4:$K$50,"Pass") -> 14 | H33: =COUNTIFS(Checklist!$E$4:$E$50,$A33,Checklist!$K$4:$K$50,"Fail") -> 0 | I33: =COUNTIFS(Checklist!$E$4:$E$50,$A33,Checklist!$K$4:$K$50,"Blocked") -> 0 | J33: =COUNTIFS(Checklist!$E$4:$E$50,$A33,Checklist!$K$4:$K$50,"N/A") -> 0 | K33: =E33-G33-H33-I33-J33 -> 0 | L33: =COUNTIFS(Checklist!$E$4:$E$50,$A33,Checklist!$J$4:$J$50,"<>Yes",Checklist!$K$4:$K$50,"<>Pass",Checklist!$K$4:$K$50,"<>N/A") -> 0 | M33: =IF(E33=0,0,(G33+H33+I33+J33)/E33) -> 1 | N33: =IF(H33>0,"Fail",IF(I33>0,"Blocked",IF(G33+H33+I33+J33=0,IF(F33=0,"Optional","Not started"),IF(L33=0,"Pass","In progress")))) -> Pass
A34: UI5 | B34: Settings: display mode, resolution, restart (in a player build) | E34: =COUNTIF(Checklist!$E$4:$E$50,$A34) -> 7 | F34: =COUNTIFS(Checklist!$E$4:$E$50,$A34,Checklist!$J$4:$J$50,"<>Yes") -> 7 | G34: =COUNTIFS(Checklist!$E$4:$E$50,$A34,Checklist!$K$4:$K$50,"Pass") -> 7 | H34: =COUNTIFS(Checklist!$E$4:$E$50,$A34,Checklist!$K$4:$K$50,"Fail") -> 0 | I34: =COUNTIFS(Checklist!$E$4:$E$50,$A34,Checklist!$K$4:$K$50,"Blocked") -> 0 | J34: =COUNTIFS(Checklist!$E$4:$E$50,$A34,Checklist!$K$4:$K$50,"N/A") -> 0 | K34: =E34-G34-H34-I34-J34 -> 0 | L34: =COUNTIFS(Checklist!$E$4:$E$50,$A34,Checklist!$J$4:$J$50,"<>Yes",Checklist!$K$4:$K$50,"<>Pass",Checklist!$K$4:$K$50,"<>N/A") -> 0 | M34: =IF(E34=0,0,(G34+H34+I34+J34)/E34) -> 1 | N34: =IF(H34>0,"Fail",IF(I34>0,"Blocked",IF(G34+H34+I34+J34=0,IF(F34=0,"Optional","Not started"),IF(L34=0,"Pass","In progress")))) -> Pass
A35: UI5 + UI6 | B35: Rows that cover both: the build, the windowed size (N49), the match in a build | E35: =COUNTIF(Checklist!$E$4:$E$50,$A35) -> 8 | F35: =COUNTIFS(Checklist!$E$4:$E$50,$A35,Checklist!$J$4:$J$50,"<>Yes") -> 8 | G35: =COUNTIFS(Checklist!$E$4:$E$50,$A35,Checklist!$K$4:$K$50,"Pass") -> 8 | H35: =COUNTIFS(Checklist!$E$4:$E$50,$A35,Checklist!$K$4:$K$50,"Fail") -> 0 | I35: =COUNTIFS(Checklist!$E$4:$E$50,$A35,Checklist!$K$4:$K$50,"Blocked") -> 0 | J35: =COUNTIFS(Checklist!$E$4:$E$50,$A35,Checklist!$K$4:$K$50,"N/A") -> 0 | K35: =E35-G35-H35-I35-J35 -> 0 | L35: =COUNTIFS(Checklist!$E$4:$E$50,$A35,Checklist!$J$4:$J$50,"<>Yes",Checklist!$K$4:$K$50,"<>Pass",Checklist!$K$4:$K$50,"<>N/A") -> 0 | M35: =IF(E35=0,0,(G35+H35+I35+J35)/E35) -> 1 | N35: =IF(H35>0,"Fail",IF(I35>0,"Blocked",IF(G35+H35+I35+J35=0,IF(F35=0,"Optional","Not started"),IF(L35=0,"Pass","In progress")))) -> Pass
A37: Check: the by-task Items column must add up to the Total row. Difference: | E37: =E28-SUM(E32:E35) -> 0

Sheet Clean-up
A1: Clean-up after the checks
A2: This round has no temporary code or asset changes. These are the settings the checks change on their own. Mark Done when each is back. Don't commit the font asset in its changed state.
A4: ID | B4: Used by | C4: What | D4: What changes | E4: Set back to | F4: How | G4: Done
A5: K1 | B5: A, B, C5 | C5: Language | D5: The locale is set to ru or ja during the checks | E5: English | F5: Editor: Main menu → Settings → English (or Localization Scene Controls). Build: Settings → English.
A6: K2 | B6: C2–C8 | C6: The build's window mode and size | D6: Unity remembers the build's last mode and size | E6: Your normal mode (fullscreen, native) | F6: Settings → Fullscreen and the native size, or start once with -screen-fullscreen 1 -screen-width 2560 -screen-height 1600.
A7: K3 | B7: A, B | C7: Assets/Fonts/MPLUSRounded1c-Medium SDF.asset | D7: Changes on its own after ru or ja text renders in the Editor (N28) | E7: HEAD: the cleared state (empty glyph and character tables) | F7: With both Editors closed: git restore "Assets/Fonts/MPLUSRounded1c-Medium SDF.asset". The file has no other uncommitted change, and HEAD is byte-identical to Codex's baselines.
A8: — | B8: Note | C8: The clone's start command | D8: The clone was started from PowerShell with its own log | E8: Nothing to undo | F8: Next time, start it the same way (Read me → Preparation 1) or from ParrelSync as before.
A9: — | B9: Note | C9: Game view presets | D9: Presets added in Preparation 6 | E9: Nothing to undo | F9: They stay in your Editor; keep them for the next checklist.
A11: Clean-up items not yet done: | D11: =COUNTIF(A5:A9,"K*")-COUNTIFS(A5:A9,"K*",G5:G9,"Yes") -> 3 | E11: must be 0 before any commit

Sheet Known issues
A1: What you may see during the checks
A3: Known and expected: don't mark a row Fail for these
A4: You see | B4: ID | C4: Notes
A5: At low sizes (e.g. 640×480) the big card covers the leftmost hand cards. | B5: UI6 | C5: Accepted in UI6. Note it in A8.1 if it bothers you (U15).
A6: Long descriptions in the big card are smaller than the other text, most of all in Russian ('Исцеляющие копыта', 'Огненный шар', 'Ледяной осколок'). Russian card names can be very small at 640×480. | B6: N51 | C6: Known: the text box is fixed by the card art. B6.1 asks for your opinion (decision W1).
A7: Selection outlines show the mana bars' boxes reaching into the banner's boxes at 1366 wide and above. | B7: N53 | C7: Accepted: the texts don't touch. Mark Fail only if the texts themselves touch.
A8: The big card stays while you click to play or discard, and a world click hides it before showing the next one. | B8: UI6 | C8: By design.
A9: Changing the Game view size while a big card is shown may hide it: the click on the size menu can count as a world click. | B9: — | C9: Editor only, not a fault. Hover the card again (A4.2).
A10: The menus (Login, Main menu, Settings, Lobby, Result) are tiny or cramped below 1024×720. | B10: UI7 | C10: Planned: only the match HUD has the compact layout so far. Don't mark B rows Fail for the menus.
A11: Settings never offers a size under 1024 × 720. | B11: UI5 | C11: By design until UI7.
A12: The warning 'Invalid mane material index.' on every pony spawn. | B12: N27 | C12: Parked by you until the mane model exists.
A13: Many plain log lines in the Console and Player.log: 'DespawnBlock' (84 at match end), 'Process called', 'Rpc called', 'RepairCalled', 'Card clicked', 'Card Alter clicked'. | B13: N34 | C13: Ungated logs; a hygiene task is pending.
A14: 'No card selected for control package.' when Confirm is pressed with no board card selected. | B14: — | C14: Expected warning.
A15: 'Send ignored: no card target was confirmed.' | B15: N20 | C15: Expected: Send needs a confirmed target. No message on screen (feature gap).
... A25: MPLUSRounded1c-Medium SDF.asset shows as modified in git status, or the clone logs 'Importer(NativeFormatImporter) generated inconsistent result' for it. | B25: N28 | C25: Expected in the Editor. Restore it before committing (Clean-up, K3).
A27: Fixed since the last checklist: mark the row Fail if you see these
A28: You see | B28: ID | C28: Checked in
A29: On the client, no big card on hover or on a board click. | B29: N50 | C29: A1, A2, A4, A6, C8.3
A30: 'CardPreviewController: no screen-space canvas found; previews are disabled.' | B30: N50 | C30: A7.1, C9.1
A31: A played card's big card disappears while the pointer rests on it in the bottom row. | B31: N52 | C31: A3.1
A32: A played card's big card stays on screen after the card has left the row. | B32: N52 | C32: A3.2
A33: Card names or descriptions unreadable in the preview at 1024×768 (except N51's long texts). | B33: N47 | C33: B2.4
A34: Button or HUD labels unreadable at small sizes. | B34: N48 | C34: B2.3
A35: The windowed build is taller than the space above the taskbar, or its bottom edge is hidden under the taskbar. | B35: N49 | C35: C2.1, C2.2
A36: 'Tried ShowPrew' in the Console or Player.log. | B36: N34 (part) | C36: A7.1, C9.1
A38: Finded
A39: When host close his application, client don’t get a result scene. But when client close app - host get result scene as winner.
